Not Found: /martcrm/assets/img/messages-1.jpg
Not Found: /martcrm/assets/img/logo.png
Not Found: /martcrm/assets/img/profile-img.jpg
Not Found: /martcrm/assets/img/messages-3.jpg
Not Found: /martcrm/assets/img/messages-2.jpg
Not Found: /martcrm/assets/img/logo.png
Not Found: /martcrm/assets/img/messages-1.jpg
Not Found: /martcrm/assets/img/profile-img.jpg
Not Found: /martcrm/assets/img/messages-2.jpg
Not Found: /martcrm/assets/img/messages-3.jpg
Not Found: /martcrm/assets/img/logo.png
Not Found: /martcrm/assets/img/messages-1.jpg
Not Found: /martcrm/assets/img/messages-2.jpg
Not Found: /martcrm/assets/img/messages-3.jpg
Not Found: /martcrm/assets/img/profile-img.jpg
Serilize =================== [{'category_id': 15, 'category_name': 'Agriculture'}]
Serilize =================== [{'category_id': 15, 'category_name': 'Agriculture'}]
Serilize =================== [{'category_id': 15, 'category_name': 'Agriculture'}]
Serilize =================== [{'category_id': 15, 'category_name': 'Agriculture'}]
Serilize =================== [{'category_id': 15, 'category_name': 'Agriculture'}]
Not Found: /martcrm/assets/img/logo.png
Not Found: /martcrm/assets/img/messages-1.jpg
Not Found: /martcrm/assets/img/messages-2.jpg
Not Found: /martcrm/assets/img/messages-3.jpg
Not Found: /martcrm/assets/img/profile-img.jpg
Not Found: /martcrm/assets/img/logo.png
Not Found: /martcrm/assets/img/messages-1.jpg
Not Found: /martcrm/assets/img/messages-2.jpg
Not Found: /martcrm/assets/img/profile-img.jpg
Not Found: /martcrm/assets/img/messages-3.jpg
Not Found: /martcrm/assets/img/logo.png
Not Found: /martcrm/assets/img/messages-1.jpg
Not Found: /martcrm/assets/img/messages-2.jpg
Not Found: /martcrm/assets/img/messages-3.jpg
Not Found: /martcrm/assets/img/profile-img.jpg
Not Found: /
Not Found: /index.php
Not Found: /index.php
Not Found: /index.php
Not Found: /index.php
Not Found: /
Not Found: /index.php
Not Found: /index.php
Not Found: /martcrm/assets/img/logo.png
Not Found: /martcrm/assets/img/messages-1.jpg
Not Found: /martcrm/assets/img/messages-2.jpg
Not Found: /martcrm/assets/img/messages-3.jpg
Not Found: /martcrm/assets/img/product-5.jpg
Not Found: /martcrm/assets/img/news-1.jpg
Not Found: /martcrm/assets/img/product-4.jpg
Not Found: /martcrm/assets/img/product-2.jpg
Not Found: /martcrm/assets/img/product-3.jpg
Not Found: /martcrm/assets/img/profile-img.jpg
Not Found: /martcrm/assets/img/product-1.jpg
Not Found: /martcrm/assets/img/news-2.jpg
Not Found: /martcrm/assets/img/news-3.jpg
Not Found: /martcrm/assets/img/news-4.jpg
Not Found: /martcrm/assets/img/news-5.jpg
Not Found: /martcrm/assets/img/logo.png
Not Found: /martcrm/assets/img/messages-1.jpg
Not Found: /martcrm/assets/img/messages-2.jpg
Not Found: /martcrm/assets/img/messages-3.jpg
Not Found: /martcrm/assets/img/profile-img.jpg
Session 1
Session None
Not Found: /martcrm/assets/img/profile-img.jpg
Not Found: /martcrm/assets/img/messages-2.jpg
Not Found: /martcrm/assets/img/messages-3.jpg
Not Found: /martcrm/assets/img/logo.png
Not Found: /martcrm/assets/img/messages-1.jpg
Internal Server Error: /martcrm/create_company
Traceback (most recent call last):
  File "/home/shivmarb/virtualenv/erp.mart4trade.com/3.8/lib/python3.8/site-packages/django/core/handlers/exception.py", line 47, in inner
    response = get_response(request)
  File "/home/shivmarb/virtualenv/erp.mart4trade.com/3.8/lib/python3.8/site-packages/django/utils/deprecation.py", line 113, in __call__
    response = self.process_request(request)
  File "/home/shivmarb/virtualenv/erp.mart4trade.com/3.8/lib/python3.8/site-packages/django/middleware/common.py", line 53, in process_request
    if self.should_redirect_with_slash(request):
  File "/home/shivmarb/virtualenv/erp.mart4trade.com/3.8/lib/python3.8/site-packages/django/middleware/common.py", line 71, in should_redirect_with_slash
    not is_valid_path(request.path_info, urlconf) and
  File "/home/shivmarb/virtualenv/erp.mart4trade.com/3.8/lib/python3.8/site-packages/django/urls/base.py", line 154, in is_valid_path
    resolve(path, urlconf)
  File "/home/shivmarb/virtualenv/erp.mart4trade.com/3.8/lib/python3.8/site-packages/django/urls/base.py", line 25, in resolve
    return get_resolver(urlconf).resolve(path)
  File "/home/shivmarb/virtualenv/erp.mart4trade.com/3.8/lib/python3.8/site-packages/django/urls/resolvers.py", line 545, in resolve
    for pattern in self.url_patterns:
  File "/home/shivmarb/virtualenv/erp.mart4trade.com/3.8/lib/python3.8/site-packages/django/utils/functional.py", line 48, in __get__
    res = instance.__dict__[self.name] = self.func(instance)
  File "/home/shivmarb/virtualenv/erp.mart4trade.com/3.8/lib/python3.8/site-packages/django/urls/resolvers.py", line 589, in url_patterns
    patterns = getattr(self.urlconf_module, "urlpatterns", self.urlconf_module)
  File "/home/shivmarb/virtualenv/erp.mart4trade.com/3.8/lib/python3.8/site-packages/django/utils/functional.py", line 48, in __get__
    res = instance.__dict__[self.name] = self.func(instance)
  File "/home/shivmarb/virtualenv/erp.mart4trade.com/3.8/lib/python3.8/site-packages/django/urls/resolvers.py", line 582, in urlconf_module
    return import_module(self.urlconf_name)
  File "/opt/alt/python38/lib64/python3.8/importlib/__init__.py", line 127, in import_module
    return _bootstrap._gcd_import(name[level:], package, level)
  File "<frozen importlib._bootstrap>", line 1014, in _gcd_import
  File "<frozen importlib._bootstrap>", line 991, in _find_and_load
  File "<frozen importlib._bootstrap>", line 975, in _find_and_load_unlocked
  File "<frozen importlib._bootstrap>", line 671, in _load_unlocked
  File "<frozen importlib._bootstrap_external>", line 843, in exec_module
  File "<frozen importlib._bootstrap>", line 219, in _call_with_frames_removed
  File "/home/shivmarb/erp.mart4trade.com/martapis/urls.py", line 24, in <module>
    path('martcrm/',include('martcrm.urls')),
  File "/home/shivmarb/virtualenv/erp.mart4trade.com/3.8/lib/python3.8/site-packages/django/urls/conf.py", line 34, in include
    urlconf_module = import_module(urlconf_module)
  File "/opt/alt/python38/lib64/python3.8/importlib/__init__.py", line 127, in import_module
    return _bootstrap._gcd_import(name[level:], package, level)
  File "<frozen importlib._bootstrap>", line 1014, in _gcd_import
  File "<frozen importlib._bootstrap>", line 991, in _find_and_load
  File "<frozen importlib._bootstrap>", line 975, in _find_and_load_unlocked
  File "<frozen importlib._bootstrap>", line 671, in _load_unlocked
  File "<frozen importlib._bootstrap_external>", line 843, in exec_module
  File "<frozen importlib._bootstrap>", line 219, in _call_with_frames_removed
  File "/home/shivmarb/erp.mart4trade.com/martcrm/urls.py", line 2, in <module>
    from . import views
  File "/home/shivmarb/erp.mart4trade.com/martcrm/views.py", line 16, in <module>
    from martcrm.helper.register_profile import register_profile
ImportError: cannot import name 'register_profile' from 'martcrm.helper.register_profile' (/home/shivmarb/erp.mart4trade.com/martcrm/helper/register_profile.py)
Internal Server Error: /favicon.ico
Traceback (most recent call last):
  File "/home/shivmarb/virtualenv/erp.mart4trade.com/3.8/lib/python3.8/site-packages/django/core/handlers/exception.py", line 47, in inner
    response = get_response(request)
  File "/home/shivmarb/virtualenv/erp.mart4trade.com/3.8/lib/python3.8/site-packages/django/utils/deprecation.py", line 113, in __call__
    response = self.process_request(request)
  File "/home/shivmarb/virtualenv/erp.mart4trade.com/3.8/lib/python3.8/site-packages/django/middleware/common.py", line 53, in process_request
    if self.should_redirect_with_slash(request):
  File "/home/shivmarb/virtualenv/erp.mart4trade.com/3.8/lib/python3.8/site-packages/django/middleware/common.py", line 71, in should_redirect_with_slash
    not is_valid_path(request.path_info, urlconf) and
  File "/home/shivmarb/virtualenv/erp.mart4trade.com/3.8/lib/python3.8/site-packages/django/urls/base.py", line 154, in is_valid_path
    resolve(path, urlconf)
  File "/home/shivmarb/virtualenv/erp.mart4trade.com/3.8/lib/python3.8/site-packages/django/urls/base.py", line 25, in resolve
    return get_resolver(urlconf).resolve(path)
  File "/home/shivmarb/virtualenv/erp.mart4trade.com/3.8/lib/python3.8/site-packages/django/urls/resolvers.py", line 545, in resolve
    for pattern in self.url_patterns:
  File "/home/shivmarb/virtualenv/erp.mart4trade.com/3.8/lib/python3.8/site-packages/django/utils/functional.py", line 48, in __get__
    res = instance.__dict__[self.name] = self.func(instance)
  File "/home/shivmarb/virtualenv/erp.mart4trade.com/3.8/lib/python3.8/site-packages/django/urls/resolvers.py", line 589, in url_patterns
    patterns = getattr(self.urlconf_module, "urlpatterns", self.urlconf_module)
  File "/home/shivmarb/virtualenv/erp.mart4trade.com/3.8/lib/python3.8/site-packages/django/utils/functional.py", line 48, in __get__
    res = instance.__dict__[self.name] = self.func(instance)
  File "/home/shivmarb/virtualenv/erp.mart4trade.com/3.8/lib/python3.8/site-packages/django/urls/resolvers.py", line 582, in urlconf_module
    return import_module(self.urlconf_name)
  File "/opt/alt/python38/lib64/python3.8/importlib/__init__.py", line 127, in import_module
    return _bootstrap._gcd_import(name[level:], package, level)
  File "<frozen importlib._bootstrap>", line 1014, in _gcd_import
  File "<frozen importlib._bootstrap>", line 991, in _find_and_load
  File "<frozen importlib._bootstrap>", line 975, in _find_and_load_unlocked
  File "<frozen importlib._bootstrap>", line 671, in _load_unlocked
  File "<frozen importlib._bootstrap_external>", line 843, in exec_module
  File "<frozen importlib._bootstrap>", line 219, in _call_with_frames_removed
  File "/home/shivmarb/erp.mart4trade.com/martapis/urls.py", line 24, in <module>
    path('martcrm/',include('martcrm.urls')),
  File "/home/shivmarb/virtualenv/erp.mart4trade.com/3.8/lib/python3.8/site-packages/django/urls/conf.py", line 34, in include
    urlconf_module = import_module(urlconf_module)
  File "/opt/alt/python38/lib64/python3.8/importlib/__init__.py", line 127, in import_module
    return _bootstrap._gcd_import(name[level:], package, level)
  File "<frozen importlib._bootstrap>", line 1014, in _gcd_import
  File "<frozen importlib._bootstrap>", line 991, in _find_and_load
  File "<frozen importlib._bootstrap>", line 975, in _find_and_load_unlocked
  File "<frozen importlib._bootstrap>", line 671, in _load_unlocked
  File "<frozen importlib._bootstrap_external>", line 843, in exec_module
  File "<frozen importlib._bootstrap>", line 219, in _call_with_frames_removed
  File "/home/shivmarb/erp.mart4trade.com/martcrm/urls.py", line 2, in <module>
    from . import views
  File "/home/shivmarb/erp.mart4trade.com/martcrm/views.py", line 16, in <module>
    from martcrm.helper.register_profile import register_profile
ImportError: cannot import name 'register_profile' from 'martcrm.helper.register_profile' (/home/shivmarb/erp.mart4trade.com/martcrm/helper/register_profile.py)
Internal Server Error: /martcrm/create_company
Traceback (most recent call last):
  File "/home/shivmarb/virtualenv/erp.mart4trade.com/3.8/lib/python3.8/site-packages/django/core/handlers/exception.py", line 47, in inner
    response = get_response(request)
  File "/home/shivmarb/virtualenv/erp.mart4trade.com/3.8/lib/python3.8/site-packages/django/utils/deprecation.py", line 113, in __call__
    response = self.process_request(request)
  File "/home/shivmarb/virtualenv/erp.mart4trade.com/3.8/lib/python3.8/site-packages/django/middleware/common.py", line 53, in process_request
    if self.should_redirect_with_slash(request):
  File "/home/shivmarb/virtualenv/erp.mart4trade.com/3.8/lib/python3.8/site-packages/django/middleware/common.py", line 71, in should_redirect_with_slash
    not is_valid_path(request.path_info, urlconf) and
  File "/home/shivmarb/virtualenv/erp.mart4trade.com/3.8/lib/python3.8/site-packages/django/urls/base.py", line 154, in is_valid_path
    resolve(path, urlconf)
  File "/home/shivmarb/virtualenv/erp.mart4trade.com/3.8/lib/python3.8/site-packages/django/urls/base.py", line 25, in resolve
    return get_resolver(urlconf).resolve(path)
  File "/home/shivmarb/virtualenv/erp.mart4trade.com/3.8/lib/python3.8/site-packages/django/urls/resolvers.py", line 545, in resolve
    for pattern in self.url_patterns:
  File "/home/shivmarb/virtualenv/erp.mart4trade.com/3.8/lib/python3.8/site-packages/django/utils/functional.py", line 48, in __get__
    res = instance.__dict__[self.name] = self.func(instance)
  File "/home/shivmarb/virtualenv/erp.mart4trade.com/3.8/lib/python3.8/site-packages/django/urls/resolvers.py", line 589, in url_patterns
    patterns = getattr(self.urlconf_module, "urlpatterns", self.urlconf_module)
  File "/home/shivmarb/virtualenv/erp.mart4trade.com/3.8/lib/python3.8/site-packages/django/utils/functional.py", line 48, in __get__
    res = instance.__dict__[self.name] = self.func(instance)
  File "/home/shivmarb/virtualenv/erp.mart4trade.com/3.8/lib/python3.8/site-packages/django/urls/resolvers.py", line 582, in urlconf_module
    return import_module(self.urlconf_name)
  File "/opt/alt/python38/lib64/python3.8/importlib/__init__.py", line 127, in import_module
    return _bootstrap._gcd_import(name[level:], package, level)
  File "<frozen importlib._bootstrap>", line 1014, in _gcd_import
  File "<frozen importlib._bootstrap>", line 991, in _find_and_load
  File "<frozen importlib._bootstrap>", line 975, in _find_and_load_unlocked
  File "<frozen importlib._bootstrap>", line 671, in _load_unlocked
  File "<frozen importlib._bootstrap_external>", line 843, in exec_module
  File "<frozen importlib._bootstrap>", line 219, in _call_with_frames_removed
  File "/home/shivmarb/erp.mart4trade.com/martapis/urls.py", line 24, in <module>
    path('martcrm/',include('martcrm.urls')),
  File "/home/shivmarb/virtualenv/erp.mart4trade.com/3.8/lib/python3.8/site-packages/django/urls/conf.py", line 34, in include
    urlconf_module = import_module(urlconf_module)
  File "/opt/alt/python38/lib64/python3.8/importlib/__init__.py", line 127, in import_module
    return _bootstrap._gcd_import(name[level:], package, level)
  File "<frozen importlib._bootstrap>", line 1014, in _gcd_import
  File "<frozen importlib._bootstrap>", line 991, in _find_and_load
  File "<frozen importlib._bootstrap>", line 975, in _find_and_load_unlocked
  File "<frozen importlib._bootstrap>", line 671, in _load_unlocked
  File "<frozen importlib._bootstrap_external>", line 843, in exec_module
  File "<frozen importlib._bootstrap>", line 219, in _call_with_frames_removed
  File "/home/shivmarb/erp.mart4trade.com/martcrm/urls.py", line 2, in <module>
    from . import views
  File "/home/shivmarb/erp.mart4trade.com/martcrm/views.py", line 16, in <module>
    from martcrm.helper.register_profile import register_profile
ImportError: cannot import name 'register_profile' from 'martcrm.helper.register_profile' (/home/shivmarb/erp.mart4trade.com/martcrm/helper/register_profile.py)
Internal Server Error: /favicon.ico
Traceback (most recent call last):
  File "/home/shivmarb/virtualenv/erp.mart4trade.com/3.8/lib/python3.8/site-packages/django/core/handlers/exception.py", line 47, in inner
    response = get_response(request)
  File "/home/shivmarb/virtualenv/erp.mart4trade.com/3.8/lib/python3.8/site-packages/django/utils/deprecation.py", line 113, in __call__
    response = self.process_request(request)
  File "/home/shivmarb/virtualenv/erp.mart4trade.com/3.8/lib/python3.8/site-packages/django/middleware/common.py", line 53, in process_request
    if self.should_redirect_with_slash(request):
  File "/home/shivmarb/virtualenv/erp.mart4trade.com/3.8/lib/python3.8/site-packages/django/middleware/common.py", line 71, in should_redirect_with_slash
    not is_valid_path(request.path_info, urlconf) and
  File "/home/shivmarb/virtualenv/erp.mart4trade.com/3.8/lib/python3.8/site-packages/django/urls/base.py", line 154, in is_valid_path
    resolve(path, urlconf)
  File "/home/shivmarb/virtualenv/erp.mart4trade.com/3.8/lib/python3.8/site-packages/django/urls/base.py", line 25, in resolve
    return get_resolver(urlconf).resolve(path)
  File "/home/shivmarb/virtualenv/erp.mart4trade.com/3.8/lib/python3.8/site-packages/django/urls/resolvers.py", line 545, in resolve
    for pattern in self.url_patterns:
  File "/home/shivmarb/virtualenv/erp.mart4trade.com/3.8/lib/python3.8/site-packages/django/utils/functional.py", line 48, in __get__
    res = instance.__dict__[self.name] = self.func(instance)
  File "/home/shivmarb/virtualenv/erp.mart4trade.com/3.8/lib/python3.8/site-packages/django/urls/resolvers.py", line 589, in url_patterns
    patterns = getattr(self.urlconf_module, "urlpatterns", self.urlconf_module)
  File "/home/shivmarb/virtualenv/erp.mart4trade.com/3.8/lib/python3.8/site-packages/django/utils/functional.py", line 48, in __get__
    res = instance.__dict__[self.name] = self.func(instance)
  File "/home/shivmarb/virtualenv/erp.mart4trade.com/3.8/lib/python3.8/site-packages/django/urls/resolvers.py", line 582, in urlconf_module
    return import_module(self.urlconf_name)
  File "/opt/alt/python38/lib64/python3.8/importlib/__init__.py", line 127, in import_module
    return _bootstrap._gcd_import(name[level:], package, level)
  File "<frozen importlib._bootstrap>", line 1014, in _gcd_import
  File "<frozen importlib._bootstrap>", line 991, in _find_and_load
  File "<frozen importlib._bootstrap>", line 975, in _find_and_load_unlocked
  File "<frozen importlib._bootstrap>", line 671, in _load_unlocked
  File "<frozen importlib._bootstrap_external>", line 843, in exec_module
  File "<frozen importlib._bootstrap>", line 219, in _call_with_frames_removed
  File "/home/shivmarb/erp.mart4trade.com/martapis/urls.py", line 24, in <module>
    path('martcrm/',include('martcrm.urls')),
  File "/home/shivmarb/virtualenv/erp.mart4trade.com/3.8/lib/python3.8/site-packages/django/urls/conf.py", line 34, in include
    urlconf_module = import_module(urlconf_module)
  File "/opt/alt/python38/lib64/python3.8/importlib/__init__.py", line 127, in import_module
    return _bootstrap._gcd_import(name[level:], package, level)
  File "<frozen importlib._bootstrap>", line 1014, in _gcd_import
  File "<frozen importlib._bootstrap>", line 991, in _find_and_load
  File "<frozen importlib._bootstrap>", line 975, in _find_and_load_unlocked
  File "<frozen importlib._bootstrap>", line 671, in _load_unlocked
  File "<frozen importlib._bootstrap_external>", line 843, in exec_module
  File "<frozen importlib._bootstrap>", line 219, in _call_with_frames_removed
  File "/home/shivmarb/erp.mart4trade.com/martcrm/urls.py", line 2, in <module>
    from . import views
  File "/home/shivmarb/erp.mart4trade.com/martcrm/views.py", line 16, in <module>
    from martcrm.helper.register_profile import register_profile
ImportError: cannot import name 'register_profile' from 'martcrm.helper.register_profile' (/home/shivmarb/erp.mart4trade.com/martcrm/helper/register_profile.py)
Internal Server Error: /martcrm/create_company
Traceback (most recent call last):
  File "/home/shivmarb/virtualenv/erp.mart4trade.com/3.8/lib/python3.8/site-packages/django/core/handlers/exception.py", line 47, in inner
    response = get_response(request)
  File "/home/shivmarb/virtualenv/erp.mart4trade.com/3.8/lib/python3.8/site-packages/django/utils/deprecation.py", line 113, in __call__
    response = self.process_request(request)
  File "/home/shivmarb/virtualenv/erp.mart4trade.com/3.8/lib/python3.8/site-packages/django/middleware/common.py", line 53, in process_request
    if self.should_redirect_with_slash(request):
  File "/home/shivmarb/virtualenv/erp.mart4trade.com/3.8/lib/python3.8/site-packages/django/middleware/common.py", line 71, in should_redirect_with_slash
    not is_valid_path(request.path_info, urlconf) and
  File "/home/shivmarb/virtualenv/erp.mart4trade.com/3.8/lib/python3.8/site-packages/django/urls/base.py", line 154, in is_valid_path
    resolve(path, urlconf)
  File "/home/shivmarb/virtualenv/erp.mart4trade.com/3.8/lib/python3.8/site-packages/django/urls/base.py", line 25, in resolve
    return get_resolver(urlconf).resolve(path)
  File "/home/shivmarb/virtualenv/erp.mart4trade.com/3.8/lib/python3.8/site-packages/django/urls/resolvers.py", line 545, in resolve
    for pattern in self.url_patterns:
  File "/home/shivmarb/virtualenv/erp.mart4trade.com/3.8/lib/python3.8/site-packages/django/utils/functional.py", line 48, in __get__
    res = instance.__dict__[self.name] = self.func(instance)
  File "/home/shivmarb/virtualenv/erp.mart4trade.com/3.8/lib/python3.8/site-packages/django/urls/resolvers.py", line 589, in url_patterns
    patterns = getattr(self.urlconf_module, "urlpatterns", self.urlconf_module)
  File "/home/shivmarb/virtualenv/erp.mart4trade.com/3.8/lib/python3.8/site-packages/django/utils/functional.py", line 48, in __get__
    res = instance.__dict__[self.name] = self.func(instance)
  File "/home/shivmarb/virtualenv/erp.mart4trade.com/3.8/lib/python3.8/site-packages/django/urls/resolvers.py", line 582, in urlconf_module
    return import_module(self.urlconf_name)
  File "/opt/alt/python38/lib64/python3.8/importlib/__init__.py", line 127, in import_module
    return _bootstrap._gcd_import(name[level:], package, level)
  File "<frozen importlib._bootstrap>", line 1014, in _gcd_import
  File "<frozen importlib._bootstrap>", line 991, in _find_and_load
  File "<frozen importlib._bootstrap>", line 975, in _find_and_load_unlocked
  File "<frozen importlib._bootstrap>", line 671, in _load_unlocked
  File "<frozen importlib._bootstrap_external>", line 843, in exec_module
  File "<frozen importlib._bootstrap>", line 219, in _call_with_frames_removed
  File "/home/shivmarb/erp.mart4trade.com/martapis/urls.py", line 24, in <module>
    path('martcrm/',include('martcrm.urls')),
  File "/home/shivmarb/virtualenv/erp.mart4trade.com/3.8/lib/python3.8/site-packages/django/urls/conf.py", line 34, in include
    urlconf_module = import_module(urlconf_module)
  File "/opt/alt/python38/lib64/python3.8/importlib/__init__.py", line 127, in import_module
    return _bootstrap._gcd_import(name[level:], package, level)
  File "<frozen importlib._bootstrap>", line 1014, in _gcd_import
  File "<frozen importlib._bootstrap>", line 991, in _find_and_load
  File "<frozen importlib._bootstrap>", line 975, in _find_and_load_unlocked
  File "<frozen importlib._bootstrap>", line 671, in _load_unlocked
  File "<frozen importlib._bootstrap_external>", line 843, in exec_module
  File "<frozen importlib._bootstrap>", line 219, in _call_with_frames_removed
  File "/home/shivmarb/erp.mart4trade.com/martcrm/urls.py", line 2, in <module>
    from . import views
  File "/home/shivmarb/erp.mart4trade.com/martcrm/views.py", line 16, in <module>
    from martcrm.helper.register_profile import register_profile
ImportError: cannot import name 'register_profile' from 'martcrm.helper.register_profile' (/home/shivmarb/erp.mart4trade.com/martcrm/helper/register_profile.py)
Internal Server Error: /favicon.ico
Traceback (most recent call last):
  File "/home/shivmarb/virtualenv/erp.mart4trade.com/3.8/lib/python3.8/site-packages/django/core/handlers/exception.py", line 47, in inner
    response = get_response(request)
  File "/home/shivmarb/virtualenv/erp.mart4trade.com/3.8/lib/python3.8/site-packages/django/utils/deprecation.py", line 113, in __call__
    response = self.process_request(request)
  File "/home/shivmarb/virtualenv/erp.mart4trade.com/3.8/lib/python3.8/site-packages/django/middleware/common.py", line 53, in process_request
    if self.should_redirect_with_slash(request):
  File "/home/shivmarb/virtualenv/erp.mart4trade.com/3.8/lib/python3.8/site-packages/django/middleware/common.py", line 71, in should_redirect_with_slash
    not is_valid_path(request.path_info, urlconf) and
  File "/home/shivmarb/virtualenv/erp.mart4trade.com/3.8/lib/python3.8/site-packages/django/urls/base.py", line 154, in is_valid_path
    resolve(path, urlconf)
  File "/home/shivmarb/virtualenv/erp.mart4trade.com/3.8/lib/python3.8/site-packages/django/urls/base.py", line 25, in resolve
    return get_resolver(urlconf).resolve(path)
  File "/home/shivmarb/virtualenv/erp.mart4trade.com/3.8/lib/python3.8/site-packages/django/urls/resolvers.py", line 545, in resolve
    for pattern in self.url_patterns:
  File "/home/shivmarb/virtualenv/erp.mart4trade.com/3.8/lib/python3.8/site-packages/django/utils/functional.py", line 48, in __get__
    res = instance.__dict__[self.name] = self.func(instance)
  File "/home/shivmarb/virtualenv/erp.mart4trade.com/3.8/lib/python3.8/site-packages/django/urls/resolvers.py", line 589, in url_patterns
    patterns = getattr(self.urlconf_module, "urlpatterns", self.urlconf_module)
  File "/home/shivmarb/virtualenv/erp.mart4trade.com/3.8/lib/python3.8/site-packages/django/utils/functional.py", line 48, in __get__
    res = instance.__dict__[self.name] = self.func(instance)
  File "/home/shivmarb/virtualenv/erp.mart4trade.com/3.8/lib/python3.8/site-packages/django/urls/resolvers.py", line 582, in urlconf_module
    return import_module(self.urlconf_name)
  File "/opt/alt/python38/lib64/python3.8/importlib/__init__.py", line 127, in import_module
    return _bootstrap._gcd_import(name[level:], package, level)
  File "<frozen importlib._bootstrap>", line 1014, in _gcd_import
  File "<frozen importlib._bootstrap>", line 991, in _find_and_load
  File "<frozen importlib._bootstrap>", line 975, in _find_and_load_unlocked
  File "<frozen importlib._bootstrap>", line 671, in _load_unlocked
  File "<frozen importlib._bootstrap_external>", line 843, in exec_module
  File "<frozen importlib._bootstrap>", line 219, in _call_with_frames_removed
  File "/home/shivmarb/erp.mart4trade.com/martapis/urls.py", line 24, in <module>
    path('martcrm/',include('martcrm.urls')),
  File "/home/shivmarb/virtualenv/erp.mart4trade.com/3.8/lib/python3.8/site-packages/django/urls/conf.py", line 34, in include
    urlconf_module = import_module(urlconf_module)
  File "/opt/alt/python38/lib64/python3.8/importlib/__init__.py", line 127, in import_module
    return _bootstrap._gcd_import(name[level:], package, level)
  File "<frozen importlib._bootstrap>", line 1014, in _gcd_import
  File "<frozen importlib._bootstrap>", line 991, in _find_and_load
  File "<frozen importlib._bootstrap>", line 975, in _find_and_load_unlocked
  File "<frozen importlib._bootstrap>", line 671, in _load_unlocked
  File "<frozen importlib._bootstrap_external>", line 843, in exec_module
  File "<frozen importlib._bootstrap>", line 219, in _call_with_frames_removed
  File "/home/shivmarb/erp.mart4trade.com/martcrm/urls.py", line 2, in <module>
    from . import views
  File "/home/shivmarb/erp.mart4trade.com/martcrm/views.py", line 16, in <module>
    from martcrm.helper.register_profile import register_profile
ImportError: cannot import name 'register_profile' from 'martcrm.helper.register_profile' (/home/shivmarb/erp.mart4trade.com/martcrm/helper/register_profile.py)
Internal Server Error: /martcrm/create_company
Traceback (most recent call last):
  File "/home/shivmarb/virtualenv/erp.mart4trade.com/3.8/lib/python3.8/site-packages/django/core/handlers/exception.py", line 47, in inner
    response = get_response(request)
  File "/home/shivmarb/virtualenv/erp.mart4trade.com/3.8/lib/python3.8/site-packages/django/utils/deprecation.py", line 113, in __call__
    response = self.process_request(request)
  File "/home/shivmarb/virtualenv/erp.mart4trade.com/3.8/lib/python3.8/site-packages/django/middleware/common.py", line 53, in process_request
    if self.should_redirect_with_slash(request):
  File "/home/shivmarb/virtualenv/erp.mart4trade.com/3.8/lib/python3.8/site-packages/django/middleware/common.py", line 71, in should_redirect_with_slash
    not is_valid_path(request.path_info, urlconf) and
  File "/home/shivmarb/virtualenv/erp.mart4trade.com/3.8/lib/python3.8/site-packages/django/urls/base.py", line 154, in is_valid_path
    resolve(path, urlconf)
  File "/home/shivmarb/virtualenv/erp.mart4trade.com/3.8/lib/python3.8/site-packages/django/urls/base.py", line 25, in resolve
    return get_resolver(urlconf).resolve(path)
  File "/home/shivmarb/virtualenv/erp.mart4trade.com/3.8/lib/python3.8/site-packages/django/urls/resolvers.py", line 545, in resolve
    for pattern in self.url_patterns:
  File "/home/shivmarb/virtualenv/erp.mart4trade.com/3.8/lib/python3.8/site-packages/django/utils/functional.py", line 48, in __get__
    res = instance.__dict__[self.name] = self.func(instance)
  File "/home/shivmarb/virtualenv/erp.mart4trade.com/3.8/lib/python3.8/site-packages/django/urls/resolvers.py", line 589, in url_patterns
    patterns = getattr(self.urlconf_module, "urlpatterns", self.urlconf_module)
  File "/home/shivmarb/virtualenv/erp.mart4trade.com/3.8/lib/python3.8/site-packages/django/utils/functional.py", line 48, in __get__
    res = instance.__dict__[self.name] = self.func(instance)
  File "/home/shivmarb/virtualenv/erp.mart4trade.com/3.8/lib/python3.8/site-packages/django/urls/resolvers.py", line 582, in urlconf_module
    return import_module(self.urlconf_name)
  File "/opt/alt/python38/lib64/python3.8/importlib/__init__.py", line 127, in import_module
    return _bootstrap._gcd_import(name[level:], package, level)
  File "<frozen importlib._bootstrap>", line 1014, in _gcd_import
  File "<frozen importlib._bootstrap>", line 991, in _find_and_load
  File "<frozen importlib._bootstrap>", line 975, in _find_and_load_unlocked
  File "<frozen importlib._bootstrap>", line 671, in _load_unlocked
  File "<frozen importlib._bootstrap_external>", line 843, in exec_module
  File "<frozen importlib._bootstrap>", line 219, in _call_with_frames_removed
  File "/home/shivmarb/erp.mart4trade.com/martapis/urls.py", line 24, in <module>
    path('martcrm/',include('martcrm.urls')),
  File "/home/shivmarb/virtualenv/erp.mart4trade.com/3.8/lib/python3.8/site-packages/django/urls/conf.py", line 34, in include
    urlconf_module = import_module(urlconf_module)
  File "/opt/alt/python38/lib64/python3.8/importlib/__init__.py", line 127, in import_module
    return _bootstrap._gcd_import(name[level:], package, level)
  File "<frozen importlib._bootstrap>", line 1014, in _gcd_import
  File "<frozen importlib._bootstrap>", line 991, in _find_and_load
  File "<frozen importlib._bootstrap>", line 975, in _find_and_load_unlocked
  File "<frozen importlib._bootstrap>", line 671, in _load_unlocked
  File "<frozen importlib._bootstrap_external>", line 843, in exec_module
  File "<frozen importlib._bootstrap>", line 219, in _call_with_frames_removed
  File "/home/shivmarb/erp.mart4trade.com/martcrm/urls.py", line 2, in <module>
    from . import views
  File "/home/shivmarb/erp.mart4trade.com/martcrm/views.py", line 16, in <module>
    from martcrm.helper.register_profile import register_profile
ImportError: cannot import name 'register_profile' from 'martcrm.helper.register_profile' (/home/shivmarb/erp.mart4trade.com/martcrm/helper/register_profile.py)
Internal Server Error: /favicon.ico
Traceback (most recent call last):
  File "/home/shivmarb/virtualenv/erp.mart4trade.com/3.8/lib/python3.8/site-packages/django/core/handlers/exception.py", line 47, in inner
    response = get_response(request)
  File "/home/shivmarb/virtualenv/erp.mart4trade.com/3.8/lib/python3.8/site-packages/django/utils/deprecation.py", line 113, in __call__
    response = self.process_request(request)
  File "/home/shivmarb/virtualenv/erp.mart4trade.com/3.8/lib/python3.8/site-packages/django/middleware/common.py", line 53, in process_request
    if self.should_redirect_with_slash(request):
  File "/home/shivmarb/virtualenv/erp.mart4trade.com/3.8/lib/python3.8/site-packages/django/middleware/common.py", line 71, in should_redirect_with_slash
    not is_valid_path(request.path_info, urlconf) and
  File "/home/shivmarb/virtualenv/erp.mart4trade.com/3.8/lib/python3.8/site-packages/django/urls/base.py", line 154, in is_valid_path
    resolve(path, urlconf)
  File "/home/shivmarb/virtualenv/erp.mart4trade.com/3.8/lib/python3.8/site-packages/django/urls/base.py", line 25, in resolve
    return get_resolver(urlconf).resolve(path)
  File "/home/shivmarb/virtualenv/erp.mart4trade.com/3.8/lib/python3.8/site-packages/django/urls/resolvers.py", line 545, in resolve
    for pattern in self.url_patterns:
  File "/home/shivmarb/virtualenv/erp.mart4trade.com/3.8/lib/python3.8/site-packages/django/utils/functional.py", line 48, in __get__
    res = instance.__dict__[self.name] = self.func(instance)
  File "/home/shivmarb/virtualenv/erp.mart4trade.com/3.8/lib/python3.8/site-packages/django/urls/resolvers.py", line 589, in url_patterns
    patterns = getattr(self.urlconf_module, "urlpatterns", self.urlconf_module)
  File "/home/shivmarb/virtualenv/erp.mart4trade.com/3.8/lib/python3.8/site-packages/django/utils/functional.py", line 48, in __get__
    res = instance.__dict__[self.name] = self.func(instance)
  File "/home/shivmarb/virtualenv/erp.mart4trade.com/3.8/lib/python3.8/site-packages/django/urls/resolvers.py", line 582, in urlconf_module
    return import_module(self.urlconf_name)
  File "/opt/alt/python38/lib64/python3.8/importlib/__init__.py", line 127, in import_module
    return _bootstrap._gcd_import(name[level:], package, level)
  File "<frozen importlib._bootstrap>", line 1014, in _gcd_import
  File "<frozen importlib._bootstrap>", line 991, in _find_and_load
  File "<frozen importlib._bootstrap>", line 975, in _find_and_load_unlocked
  File "<frozen importlib._bootstrap>", line 671, in _load_unlocked
  File "<frozen importlib._bootstrap_external>", line 843, in exec_module
  File "<frozen importlib._bootstrap>", line 219, in _call_with_frames_removed
  File "/home/shivmarb/erp.mart4trade.com/martapis/urls.py", line 24, in <module>
    path('martcrm/',include('martcrm.urls')),
  File "/home/shivmarb/virtualenv/erp.mart4trade.com/3.8/lib/python3.8/site-packages/django/urls/conf.py", line 34, in include
    urlconf_module = import_module(urlconf_module)
  File "/opt/alt/python38/lib64/python3.8/importlib/__init__.py", line 127, in import_module
    return _bootstrap._gcd_import(name[level:], package, level)
  File "<frozen importlib._bootstrap>", line 1014, in _gcd_import
  File "<frozen importlib._bootstrap>", line 991, in _find_and_load
  File "<frozen importlib._bootstrap>", line 975, in _find_and_load_unlocked
  File "<frozen importlib._bootstrap>", line 671, in _load_unlocked
  File "<frozen importlib._bootstrap_external>", line 843, in exec_module
  File "<frozen importlib._bootstrap>", line 219, in _call_with_frames_removed
  File "/home/shivmarb/erp.mart4trade.com/martcrm/urls.py", line 2, in <module>
    from . import views
  File "/home/shivmarb/erp.mart4trade.com/martcrm/views.py", line 16, in <module>
    from martcrm.helper.register_profile import register_profile
ImportError: cannot import name 'register_profile' from 'martcrm.helper.register_profile' (/home/shivmarb/erp.mart4trade.com/martcrm/helper/register_profile.py)
Internal Server Error: /martcrm/create_company
Traceback (most recent call last):
  File "/home/shivmarb/virtualenv/erp.mart4trade.com/3.8/lib/python3.8/site-packages/django/core/handlers/exception.py", line 47, in inner
    response = get_response(request)
  File "/home/shivmarb/virtualenv/erp.mart4trade.com/3.8/lib/python3.8/site-packages/django/utils/deprecation.py", line 113, in __call__
    response = self.process_request(request)
  File "/home/shivmarb/virtualenv/erp.mart4trade.com/3.8/lib/python3.8/site-packages/django/middleware/common.py", line 53, in process_request
    if self.should_redirect_with_slash(request):
  File "/home/shivmarb/virtualenv/erp.mart4trade.com/3.8/lib/python3.8/site-packages/django/middleware/common.py", line 71, in should_redirect_with_slash
    not is_valid_path(request.path_info, urlconf) and
  File "/home/shivmarb/virtualenv/erp.mart4trade.com/3.8/lib/python3.8/site-packages/django/urls/base.py", line 154, in is_valid_path
    resolve(path, urlconf)
  File "/home/shivmarb/virtualenv/erp.mart4trade.com/3.8/lib/python3.8/site-packages/django/urls/base.py", line 25, in resolve
    return get_resolver(urlconf).resolve(path)
  File "/home/shivmarb/virtualenv/erp.mart4trade.com/3.8/lib/python3.8/site-packages/django/urls/resolvers.py", line 545, in resolve
    for pattern in self.url_patterns:
  File "/home/shivmarb/virtualenv/erp.mart4trade.com/3.8/lib/python3.8/site-packages/django/utils/functional.py", line 48, in __get__
    res = instance.__dict__[self.name] = self.func(instance)
  File "/home/shivmarb/virtualenv/erp.mart4trade.com/3.8/lib/python3.8/site-packages/django/urls/resolvers.py", line 589, in url_patterns
    patterns = getattr(self.urlconf_module, "urlpatterns", self.urlconf_module)
  File "/home/shivmarb/virtualenv/erp.mart4trade.com/3.8/lib/python3.8/site-packages/django/utils/functional.py", line 48, in __get__
    res = instance.__dict__[self.name] = self.func(instance)
  File "/home/shivmarb/virtualenv/erp.mart4trade.com/3.8/lib/python3.8/site-packages/django/urls/resolvers.py", line 582, in urlconf_module
    return import_module(self.urlconf_name)
  File "/opt/alt/python38/lib64/python3.8/importlib/__init__.py", line 127, in import_module
    return _bootstrap._gcd_import(name[level:], package, level)
  File "<frozen importlib._bootstrap>", line 1014, in _gcd_import
  File "<frozen importlib._bootstrap>", line 991, in _find_and_load
  File "<frozen importlib._bootstrap>", line 975, in _find_and_load_unlocked
  File "<frozen importlib._bootstrap>", line 671, in _load_unlocked
  File "<frozen importlib._bootstrap_external>", line 843, in exec_module
  File "<frozen importlib._bootstrap>", line 219, in _call_with_frames_removed
  File "/home/shivmarb/erp.mart4trade.com/martapis/urls.py", line 24, in <module>
    path('martcrm/',include('martcrm.urls')),
  File "/home/shivmarb/virtualenv/erp.mart4trade.com/3.8/lib/python3.8/site-packages/django/urls/conf.py", line 34, in include
    urlconf_module = import_module(urlconf_module)
  File "/opt/alt/python38/lib64/python3.8/importlib/__init__.py", line 127, in import_module
    return _bootstrap._gcd_import(name[level:], package, level)
  File "<frozen importlib._bootstrap>", line 1014, in _gcd_import
  File "<frozen importlib._bootstrap>", line 991, in _find_and_load
  File "<frozen importlib._bootstrap>", line 975, in _find_and_load_unlocked
  File "<frozen importlib._bootstrap>", line 671, in _load_unlocked
  File "<frozen importlib._bootstrap_external>", line 843, in exec_module
  File "<frozen importlib._bootstrap>", line 219, in _call_with_frames_removed
  File "/home/shivmarb/erp.mart4trade.com/martcrm/urls.py", line 2, in <module>
    from . import views
  File "/home/shivmarb/erp.mart4trade.com/martcrm/views.py", line 16, in <module>
    from martcrm.helper.register_profile import create_profile
ImportError: cannot import name 'create_profile' from 'martcrm.helper.register_profile' (/home/shivmarb/erp.mart4trade.com/martcrm/helper/register_profile.py)
Internal Server Error: /favicon.ico
Traceback (most recent call last):
  File "/home/shivmarb/virtualenv/erp.mart4trade.com/3.8/lib/python3.8/site-packages/django/core/handlers/exception.py", line 47, in inner
    response = get_response(request)
  File "/home/shivmarb/virtualenv/erp.mart4trade.com/3.8/lib/python3.8/site-packages/django/utils/deprecation.py", line 113, in __call__
    response = self.process_request(request)
  File "/home/shivmarb/virtualenv/erp.mart4trade.com/3.8/lib/python3.8/site-packages/django/middleware/common.py", line 53, in process_request
    if self.should_redirect_with_slash(request):
  File "/home/shivmarb/virtualenv/erp.mart4trade.com/3.8/lib/python3.8/site-packages/django/middleware/common.py", line 71, in should_redirect_with_slash
    not is_valid_path(request.path_info, urlconf) and
  File "/home/shivmarb/virtualenv/erp.mart4trade.com/3.8/lib/python3.8/site-packages/django/urls/base.py", line 154, in is_valid_path
    resolve(path, urlconf)
  File "/home/shivmarb/virtualenv/erp.mart4trade.com/3.8/lib/python3.8/site-packages/django/urls/base.py", line 25, in resolve
    return get_resolver(urlconf).resolve(path)
  File "/home/shivmarb/virtualenv/erp.mart4trade.com/3.8/lib/python3.8/site-packages/django/urls/resolvers.py", line 545, in resolve
    for pattern in self.url_patterns:
  File "/home/shivmarb/virtualenv/erp.mart4trade.com/3.8/lib/python3.8/site-packages/django/utils/functional.py", line 48, in __get__
    res = instance.__dict__[self.name] = self.func(instance)
  File "/home/shivmarb/virtualenv/erp.mart4trade.com/3.8/lib/python3.8/site-packages/django/urls/resolvers.py", line 589, in url_patterns
    patterns = getattr(self.urlconf_module, "urlpatterns", self.urlconf_module)
  File "/home/shivmarb/virtualenv/erp.mart4trade.com/3.8/lib/python3.8/site-packages/django/utils/functional.py", line 48, in __get__
    res = instance.__dict__[self.name] = self.func(instance)
  File "/home/shivmarb/virtualenv/erp.mart4trade.com/3.8/lib/python3.8/site-packages/django/urls/resolvers.py", line 582, in urlconf_module
    return import_module(self.urlconf_name)
  File "/opt/alt/python38/lib64/python3.8/importlib/__init__.py", line 127, in import_module
    return _bootstrap._gcd_import(name[level:], package, level)
  File "<frozen importlib._bootstrap>", line 1014, in _gcd_import
  File "<frozen importlib._bootstrap>", line 991, in _find_and_load
  File "<frozen importlib._bootstrap>", line 975, in _find_and_load_unlocked
  File "<frozen importlib._bootstrap>", line 671, in _load_unlocked
  File "<frozen importlib._bootstrap_external>", line 843, in exec_module
  File "<frozen importlib._bootstrap>", line 219, in _call_with_frames_removed
  File "/home/shivmarb/erp.mart4trade.com/martapis/urls.py", line 24, in <module>
    path('martcrm/',include('martcrm.urls')),
  File "/home/shivmarb/virtualenv/erp.mart4trade.com/3.8/lib/python3.8/site-packages/django/urls/conf.py", line 34, in include
    urlconf_module = import_module(urlconf_module)
  File "/opt/alt/python38/lib64/python3.8/importlib/__init__.py", line 127, in import_module
    return _bootstrap._gcd_import(name[level:], package, level)
  File "<frozen importlib._bootstrap>", line 1014, in _gcd_import
  File "<frozen importlib._bootstrap>", line 991, in _find_and_load
  File "<frozen importlib._bootstrap>", line 975, in _find_and_load_unlocked
  File "<frozen importlib._bootstrap>", line 671, in _load_unlocked
  File "<frozen importlib._bootstrap_external>", line 843, in exec_module
  File "<frozen importlib._bootstrap>", line 219, in _call_with_frames_removed
  File "/home/shivmarb/erp.mart4trade.com/martcrm/urls.py", line 2, in <module>
    from . import views
  File "/home/shivmarb/erp.mart4trade.com/martcrm/views.py", line 16, in <module>
    from martcrm.helper.register_profile import create_profile
ImportError: cannot import name 'create_profile' from 'martcrm.helper.register_profile' (/home/shivmarb/erp.mart4trade.com/martcrm/helper/register_profile.py)
Internal Server Error: /martcrm/create_company
Traceback (most recent call last):
  File "/home/shivmarb/virtualenv/erp.mart4trade.com/3.8/lib/python3.8/site-packages/django/core/handlers/exception.py", line 47, in inner
    response = get_response(request)
  File "/home/shivmarb/virtualenv/erp.mart4trade.com/3.8/lib/python3.8/site-packages/django/utils/deprecation.py", line 113, in __call__
    response = self.process_request(request)
  File "/home/shivmarb/virtualenv/erp.mart4trade.com/3.8/lib/python3.8/site-packages/django/middleware/common.py", line 53, in process_request
    if self.should_redirect_with_slash(request):
  File "/home/shivmarb/virtualenv/erp.mart4trade.com/3.8/lib/python3.8/site-packages/django/middleware/common.py", line 71, in should_redirect_with_slash
    not is_valid_path(request.path_info, urlconf) and
  File "/home/shivmarb/virtualenv/erp.mart4trade.com/3.8/lib/python3.8/site-packages/django/urls/base.py", line 154, in is_valid_path
    resolve(path, urlconf)
  File "/home/shivmarb/virtualenv/erp.mart4trade.com/3.8/lib/python3.8/site-packages/django/urls/base.py", line 25, in resolve
    return get_resolver(urlconf).resolve(path)
  File "/home/shivmarb/virtualenv/erp.mart4trade.com/3.8/lib/python3.8/site-packages/django/urls/resolvers.py", line 545, in resolve
    for pattern in self.url_patterns:
  File "/home/shivmarb/virtualenv/erp.mart4trade.com/3.8/lib/python3.8/site-packages/django/utils/functional.py", line 48, in __get__
    res = instance.__dict__[self.name] = self.func(instance)
  File "/home/shivmarb/virtualenv/erp.mart4trade.com/3.8/lib/python3.8/site-packages/django/urls/resolvers.py", line 589, in url_patterns
    patterns = getattr(self.urlconf_module, "urlpatterns", self.urlconf_module)
  File "/home/shivmarb/virtualenv/erp.mart4trade.com/3.8/lib/python3.8/site-packages/django/utils/functional.py", line 48, in __get__
    res = instance.__dict__[self.name] = self.func(instance)
  File "/home/shivmarb/virtualenv/erp.mart4trade.com/3.8/lib/python3.8/site-packages/django/urls/resolvers.py", line 582, in urlconf_module
    return import_module(self.urlconf_name)
  File "/opt/alt/python38/lib64/python3.8/importlib/__init__.py", line 127, in import_module
    return _bootstrap._gcd_import(name[level:], package, level)
  File "<frozen importlib._bootstrap>", line 1014, in _gcd_import
  File "<frozen importlib._bootstrap>", line 991, in _find_and_load
  File "<frozen importlib._bootstrap>", line 975, in _find_and_load_unlocked
  File "<frozen importlib._bootstrap>", line 671, in _load_unlocked
  File "<frozen importlib._bootstrap_external>", line 843, in exec_module
  File "<frozen importlib._bootstrap>", line 219, in _call_with_frames_removed
  File "/home/shivmarb/erp.mart4trade.com/martapis/urls.py", line 24, in <module>
    path('martcrm/',include('martcrm.urls')),
  File "/home/shivmarb/virtualenv/erp.mart4trade.com/3.8/lib/python3.8/site-packages/django/urls/conf.py", line 34, in include
    urlconf_module = import_module(urlconf_module)
  File "/opt/alt/python38/lib64/python3.8/importlib/__init__.py", line 127, in import_module
    return _bootstrap._gcd_import(name[level:], package, level)
  File "<frozen importlib._bootstrap>", line 1014, in _gcd_import
  File "<frozen importlib._bootstrap>", line 991, in _find_and_load
  File "<frozen importlib._bootstrap>", line 975, in _find_and_load_unlocked
  File "<frozen importlib._bootstrap>", line 671, in _load_unlocked
  File "<frozen importlib._bootstrap_external>", line 843, in exec_module
  File "<frozen importlib._bootstrap>", line 219, in _call_with_frames_removed
  File "/home/shivmarb/erp.mart4trade.com/martcrm/urls.py", line 2, in <module>
    from . import views
  File "/home/shivmarb/erp.mart4trade.com/martcrm/views.py", line 16, in <module>
    from martcrm.helper.register_profile import create_profile
ImportError: cannot import name 'create_profile' from 'martcrm.helper.register_profile' (/home/shivmarb/erp.mart4trade.com/martcrm/helper/register_profile.py)
Internal Server Error: /favicon.ico
Traceback (most recent call last):
  File "/home/shivmarb/virtualenv/erp.mart4trade.com/3.8/lib/python3.8/site-packages/django/core/handlers/exception.py", line 47, in inner
    response = get_response(request)
  File "/home/shivmarb/virtualenv/erp.mart4trade.com/3.8/lib/python3.8/site-packages/django/utils/deprecation.py", line 113, in __call__
    response = self.process_request(request)
  File "/home/shivmarb/virtualenv/erp.mart4trade.com/3.8/lib/python3.8/site-packages/django/middleware/common.py", line 53, in process_request
    if self.should_redirect_with_slash(request):
  File "/home/shivmarb/virtualenv/erp.mart4trade.com/3.8/lib/python3.8/site-packages/django/middleware/common.py", line 71, in should_redirect_with_slash
    not is_valid_path(request.path_info, urlconf) and
  File "/home/shivmarb/virtualenv/erp.mart4trade.com/3.8/lib/python3.8/site-packages/django/urls/base.py", line 154, in is_valid_path
    resolve(path, urlconf)
  File "/home/shivmarb/virtualenv/erp.mart4trade.com/3.8/lib/python3.8/site-packages/django/urls/base.py", line 25, in resolve
    return get_resolver(urlconf).resolve(path)
  File "/home/shivmarb/virtualenv/erp.mart4trade.com/3.8/lib/python3.8/site-packages/django/urls/resolvers.py", line 545, in resolve
    for pattern in self.url_patterns:
  File "/home/shivmarb/virtualenv/erp.mart4trade.com/3.8/lib/python3.8/site-packages/django/utils/functional.py", line 48, in __get__
    res = instance.__dict__[self.name] = self.func(instance)
  File "/home/shivmarb/virtualenv/erp.mart4trade.com/3.8/lib/python3.8/site-packages/django/urls/resolvers.py", line 589, in url_patterns
    patterns = getattr(self.urlconf_module, "urlpatterns", self.urlconf_module)
  File "/home/shivmarb/virtualenv/erp.mart4trade.com/3.8/lib/python3.8/site-packages/django/utils/functional.py", line 48, in __get__
    res = instance.__dict__[self.name] = self.func(instance)
  File "/home/shivmarb/virtualenv/erp.mart4trade.com/3.8/lib/python3.8/site-packages/django/urls/resolvers.py", line 582, in urlconf_module
    return import_module(self.urlconf_name)
  File "/opt/alt/python38/lib64/python3.8/importlib/__init__.py", line 127, in import_module
    return _bootstrap._gcd_import(name[level:], package, level)
  File "<frozen importlib._bootstrap>", line 1014, in _gcd_import
  File "<frozen importlib._bootstrap>", line 991, in _find_and_load
  File "<frozen importlib._bootstrap>", line 975, in _find_and_load_unlocked
  File "<frozen importlib._bootstrap>", line 671, in _load_unlocked
  File "<frozen importlib._bootstrap_external>", line 843, in exec_module
  File "<frozen importlib._bootstrap>", line 219, in _call_with_frames_removed
  File "/home/shivmarb/erp.mart4trade.com/martapis/urls.py", line 24, in <module>
    path('martcrm/',include('martcrm.urls')),
  File "/home/shivmarb/virtualenv/erp.mart4trade.com/3.8/lib/python3.8/site-packages/django/urls/conf.py", line 34, in include
    urlconf_module = import_module(urlconf_module)
  File "/opt/alt/python38/lib64/python3.8/importlib/__init__.py", line 127, in import_module
    return _bootstrap._gcd_import(name[level:], package, level)
  File "<frozen importlib._bootstrap>", line 1014, in _gcd_import
  File "<frozen importlib._bootstrap>", line 991, in _find_and_load
  File "<frozen importlib._bootstrap>", line 975, in _find_and_load_unlocked
  File "<frozen importlib._bootstrap>", line 671, in _load_unlocked
  File "<frozen importlib._bootstrap_external>", line 843, in exec_module
  File "<frozen importlib._bootstrap>", line 219, in _call_with_frames_removed
  File "/home/shivmarb/erp.mart4trade.com/martcrm/urls.py", line 2, in <module>
    from . import views
  File "/home/shivmarb/erp.mart4trade.com/martcrm/views.py", line 16, in <module>
    from martcrm.helper.register_profile import create_profile
ImportError: cannot import name 'create_profile' from 'martcrm.helper.register_profile' (/home/shivmarb/erp.mart4trade.com/martcrm/helper/register_profile.py)
Not Found: /martcrm/assets/img/logo.png
Not Found: /martcrm/assets/img/messages-1.jpg
Not Found: /martcrm/assets/img/messages-2.jpg
Not Found: /martcrm/assets/img/messages-3.jpg
Not Found: /martcrm/assets/img/profile-img.jpg
Not Found: /martcrm/assets/img/favicon.png
Not Found: /martcrm/assets/img/logo.png
Not Found: /martcrm/assets/img/messages-1.jpg
Not Found: /martcrm/assets/img/messages-2.jpg
Not Found: /martcrm/assets/img/messages-3.jpg
Not Found: /martcrm/assets/img/profile-img.jpg
Not Found: /index.php
Not Found: /index.php
Internal Server Error: /martcrm/create_company
Traceback (most recent call last):
  File "/home/shivmarb/virtualenv/erp.mart4trade.com/3.8/lib/python3.8/site-packages/django/core/handlers/exception.py", line 47, in inner
    response = get_response(request)
  File "/home/shivmarb/virtualenv/erp.mart4trade.com/3.8/lib/python3.8/site-packages/django/core/handlers/base.py", line 179, in _get_response
    response = wrapped_callback(request, *callback_args, **callback_kwargs)
  File "/home/shivmarb/erp.mart4trade.com/martcrm/views.py", line 274, in create_company
    profile_obj = create_profile(**kwargs)
  File "/home/shivmarb/erp.mart4trade.com/martcrm/helper/register_profile.py", line 68, in create_profile
    return profile_id
UnboundLocalError: local variable 'profile_id' referenced before assignment
Not Found: /favicon.ico
Internal Server Error: /martcrm/create_company
Traceback (most recent call last):
  File "/home/shivmarb/virtualenv/erp.mart4trade.com/3.8/lib/python3.8/site-packages/django/core/handlers/exception.py", line 47, in inner
    response = get_response(request)
  File "/home/shivmarb/virtualenv/erp.mart4trade.com/3.8/lib/python3.8/site-packages/django/core/handlers/base.py", line 179, in _get_response
    response = wrapped_callback(request, *callback_args, **callback_kwargs)
  File "/home/shivmarb/erp.mart4trade.com/martcrm/views.py", line 274, in create_company
    profile_obj = create_profile(**kwargs)
  File "/home/shivmarb/erp.mart4trade.com/martcrm/helper/register_profile.py", line 68, in create_profile
    print(f"There is come error {ex}")
UnboundLocalError: local variable 'profile_id' referenced before assignment
There is come error ProfileMaster() got an unexpected keyword argument 'est'
There is come error ProfileMaster() got an unexpected keyword argument 'est'
Not Found: /martcrm/assets/img/logo.png
Not Found: /martcrm/assets/img/messages-1.jpg
Not Found: /martcrm/assets/img/messages-2.jpg
Not Found: /martcrm/assets/img/messages-3.jpg
Not Found: /martcrm/assets/img/profile-img.jpg
There is come error ProfileMaster() got an unexpected keyword argument 'est'
Not Found: /martcrm/assets/img/logo.png
Not Found: /martcrm/assets/img/messages-1.jpg
Not Found: /martcrm/assets/img/messages-2.jpg
Not Found: /martcrm/assets/img/messages-3.jpg
Not Found: /martcrm/assets/img/profile-img.jpg
Not Found: /martcrm/assets/img/logo.png
Not Found: /martcrm/assets/img/messages-1.jpg
Not Found: /martcrm/assets/img/messages-2.jpg
Not Found: /martcrm/assets/img/messages-3.jpg
Not Found: /martcrm/assets/img/profile-img.jpg
Not Found: /index.php
Not Found: /index.php
There is come error null value in column "auto_registered" violates not-null constraint
DETAIL:  Failing row contains (2, shaileshgola, rahul123!@#, null, Shailesh, , KUMAR, Software Developer, null, null, null, null, null, null, null, , , null, null, null, null, null, null, null, null, null, null, null, null, null, , null, null, null, null, null, null, null, null, null, null, null, null, null, null, null, null, null, null, null).

There is come error null value in column "auto_registered" violates not-null constraint
DETAIL:  Failing row contains (1, shaileshgola, rahul123!@#, null, Shailesh, , KUMAR, Software Developer, null, null, null, null, null, null, null, , , null, null, null, null, null, null, null, null, null, null, null, null, null, , null, null, null, null, null, null, null, null, null, null, null, null, null, null, null, null, null, null, null).

Not Found: /martcrm/assets/img/logo.png
Not Found: /martcrm/assets/img/messages-1.jpg
Not Found: /martcrm/assets/img/messages-3.jpg
Not Found: /martcrm/assets/img/messages-2.jpg
Not Found: /martcrm/assets/img/profile-img.jpg
Not Found: /martcrm/assets/img/logo.png
Not Found: /martcrm/assets/img/messages-1.jpg
Not Found: /martcrm/assets/img/messages-2.jpg
Not Found: /martcrm/assets/img/profile-img.jpg
Not Found: /martcrm/assets/img/messages-3.jpg
There is come error null value in column "auto_registered" violates not-null constraint
DETAIL:  Failing row contains (3, shaileshgola, rahul123!@#, null, Shailesh, , KUMAR, Software Developer, null, null, null, null, null, null, null, , , null, null, null, null, null, null, null, null, null, null, null, null, null, , null, null, null, null, null, null, null, null, null, null, null, null, null, null, null, null, null, null, null).

Profile====Obj == None
There is some error in company registration 'ascii' codec can't encode character '\u201c' in position 22: ordinal not in range(128)
Not Found: /martcrm/assets/img/profile-img.jpg
Not Found: /martcrm/assets/img/logo.png
Not Found: /martcrm/assets/img/messages-2.jpg
Not Found: /martcrm/assets/img/messages-1.jpg
Not Found: /martcrm/assets/img/profile-img.jpg
Not Found: /martcrm/assets/img/messages-3.jpg
There is some error in company registration 'ascii' codec can't encode character '\u201c' in position 22: ordinal not in range(128)
Not Found: /martcrm/assets/img/logo.png
Not Found: /martcrm/assets/img/messages-1.jpg
Not Found: /martcrm/assets/img/messages-3.jpg
Not Found: /martcrm/assets/img/messages-2.jpg
Not Found: /martcrm/assets/img/profile-img.jpg
Not Found: /martcrm/assets/img/logo.png
Not Found: /martcrm/assets/img/messages-1.jpg
Not Found: /martcrm/assets/img/messages-2.jpg
Not Found: /martcrm/assets/img/messages-3.jpg
Not Found: /martcrm/assets/img/profile-img.jpg
Email obj ====== EmailMaster object (6)
mobile_obj ====== MobileMaster object (6)
user_obj ====== UserAccounts object (6)
There is some error in company registration 'ascii' codec can't encode character '\u201c' in position 22: ordinal not in range(128)
Email obj ====== EmailMaster object (7)
mobile_obj ====== MobileMaster object (7)
user_obj ====== UserAccounts object (7)
There is some error in company registration 'ascii' codec can't encode character '\u201c' in position 22: ordinal not in range(128)
Not Found: /martcrm/assets/img/logo.png
Not Found: /martcrm/assets/img/messages-1.jpg
Not Found: /martcrm/assets/img/messages-2.jpg
Not Found: /martcrm/assets/img/messages-3.jpg
Not Found: /martcrm/assets/img/profile-img.jpg
There is some error in company registration name 'request' is not defined
Internal Server Error: /martcrm/create_company
Traceback (most recent call last):
  File "/home/shivmarb/virtualenv/erp.mart4trade.com/3.8/lib/python3.8/site-packages/django/core/handlers/exception.py", line 47, in inner
    response = get_response(request)
  File "/home/shivmarb/virtualenv/erp.mart4trade.com/3.8/lib/python3.8/site-packages/django/utils/deprecation.py", line 113, in __call__
    response = self.process_request(request)
  File "/home/shivmarb/virtualenv/erp.mart4trade.com/3.8/lib/python3.8/site-packages/django/middleware/common.py", line 53, in process_request
    if self.should_redirect_with_slash(request):
  File "/home/shivmarb/virtualenv/erp.mart4trade.com/3.8/lib/python3.8/site-packages/django/middleware/common.py", line 71, in should_redirect_with_slash
    not is_valid_path(request.path_info, urlconf) and
  File "/home/shivmarb/virtualenv/erp.mart4trade.com/3.8/lib/python3.8/site-packages/django/urls/base.py", line 154, in is_valid_path
    resolve(path, urlconf)
  File "/home/shivmarb/virtualenv/erp.mart4trade.com/3.8/lib/python3.8/site-packages/django/urls/base.py", line 25, in resolve
    return get_resolver(urlconf).resolve(path)
  File "/home/shivmarb/virtualenv/erp.mart4trade.com/3.8/lib/python3.8/site-packages/django/urls/resolvers.py", line 545, in resolve
    for pattern in self.url_patterns:
  File "/home/shivmarb/virtualenv/erp.mart4trade.com/3.8/lib/python3.8/site-packages/django/utils/functional.py", line 48, in __get__
    res = instance.__dict__[self.name] = self.func(instance)
  File "/home/shivmarb/virtualenv/erp.mart4trade.com/3.8/lib/python3.8/site-packages/django/urls/resolvers.py", line 589, in url_patterns
    patterns = getattr(self.urlconf_module, "urlpatterns", self.urlconf_module)
  File "/home/shivmarb/virtualenv/erp.mart4trade.com/3.8/lib/python3.8/site-packages/django/utils/functional.py", line 48, in __get__
    res = instance.__dict__[self.name] = self.func(instance)
  File "/home/shivmarb/virtualenv/erp.mart4trade.com/3.8/lib/python3.8/site-packages/django/urls/resolvers.py", line 582, in urlconf_module
    return import_module(self.urlconf_name)
  File "/opt/alt/python38/lib64/python3.8/importlib/__init__.py", line 127, in import_module
    return _bootstrap._gcd_import(name[level:], package, level)
  File "<frozen importlib._bootstrap>", line 1014, in _gcd_import
  File "<frozen importlib._bootstrap>", line 991, in _find_and_load
  File "<frozen importlib._bootstrap>", line 975, in _find_and_load_unlocked
  File "<frozen importlib._bootstrap>", line 671, in _load_unlocked
  File "<frozen importlib._bootstrap_external>", line 843, in exec_module
  File "<frozen importlib._bootstrap>", line 219, in _call_with_frames_removed
  File "/home/shivmarb/erp.mart4trade.com/martapis/urls.py", line 24, in <module>
    path('martcrm/',include('martcrm.urls')),
  File "/home/shivmarb/virtualenv/erp.mart4trade.com/3.8/lib/python3.8/site-packages/django/urls/conf.py", line 34, in include
    urlconf_module = import_module(urlconf_module)
  File "/opt/alt/python38/lib64/python3.8/importlib/__init__.py", line 127, in import_module
    return _bootstrap._gcd_import(name[level:], package, level)
  File "<frozen importlib._bootstrap>", line 1014, in _gcd_import
  File "<frozen importlib._bootstrap>", line 991, in _find_and_load
  File "<frozen importlib._bootstrap>", line 975, in _find_and_load_unlocked
  File "<frozen importlib._bootstrap>", line 671, in _load_unlocked
  File "<frozen importlib._bootstrap_external>", line 843, in exec_module
  File "<frozen importlib._bootstrap>", line 219, in _call_with_frames_removed
  File "/home/shivmarb/erp.mart4trade.com/martcrm/urls.py", line 2, in <module>
    from . import views
  File "/home/shivmarb/erp.mart4trade.com/martcrm/views.py", line 16, in <module>
    from martcrm.helper.register_profile import create_profile
  File "/home/shivmarb/erp.mart4trade.com/martcrm/helper/register_profile.py", line 13, in <module>
    from .models import EmailMaster, MobileMaster, UserAccounts, ProfileMaster, AccountEmails, AccountMobiles, AccountProfiles
ModuleNotFoundError: No module named 'martcrm.helper.models'
Not Found: /martcrm/assets/img/logo.png
Not Found: /martcrm/assets/img/messages-1.jpg
Not Found: /martcrm/assets/img/messages-2.jpg
Not Found: /martcrm/assets/img/messages-3.jpg
Not Found: /martcrm/assets/img/profile-img.jpg
Not Found: /martcrm/assets/img/logo.png
Not Found: /martcrm/assets/img/messages-1.jpg
Not Found: /martcrm/assets/img/messages-2.jpg
Not Found: /martcrm/assets/img/messages-3.jpg
Not Found: /martcrm/assets/img/profile-img.jpg
Not Found: /martcrm/assets/img/logo.png
Not Found: /martcrm/assets/img/messages-1.jpg
Not Found: /martcrm/assets/img/messages-2.jpg
Not Found: /martcrm/assets/img/messages-3.jpg
Not Found: /martcrm/assets/img/profile-img.jpg
Not Found: /martcrm/assets/img/logo.png
Not Found: /martcrm/assets/img/messages-1.jpg
Not Found: /martcrm/assets/img/messages-2.jpg
Not Found: /martcrm/assets/img/messages-3.jpg
Not Found: /martcrm/assets/img/profile-img.jpg
There is some error in company registration name 'request' is not defined
There is some error in company registration name 'request' is not defined
Internal Server Error: /martcrm/create_company
Traceback (most recent call last):
  File "/home/shivmarb/erp.mart4trade.com/martcrm/helper/register_profile.py", line 22, in create_profile
    profile_obj = ProfileMaster.objects.create(
  File "/home/shivmarb/virtualenv/erp.mart4trade.com/3.8/lib/python3.8/site-packages/django/db/models/manager.py", line 85, in manager_method
    return getattr(self.get_queryset(), name)(*args, **kwargs)
  File "/home/shivmarb/virtualenv/erp.mart4trade.com/3.8/lib/python3.8/site-packages/django/db/models/query.py", line 447, in create
    obj.save(force_insert=True, using=self.db)
  File "/home/shivmarb/virtualenv/erp.mart4trade.com/3.8/lib/python3.8/site-packages/django/db/models/base.py", line 750, in save
    self.save_base(using=using, force_insert=force_insert,
  File "/home/shivmarb/virtualenv/erp.mart4trade.com/3.8/lib/python3.8/site-packages/django/db/models/base.py", line 787, in save_base
    updated = self._save_table(
  File "/home/shivmarb/virtualenv/erp.mart4trade.com/3.8/lib/python3.8/site-packages/django/db/models/base.py", line 892, in _save_table
    results = self._do_insert(cls._base_manager, using, fields, returning_fields, raw)
  File "/home/shivmarb/virtualenv/erp.mart4trade.com/3.8/lib/python3.8/site-packages/django/db/models/base.py", line 930, in _do_insert
    return manager._insert(
  File "/home/shivmarb/virtualenv/erp.mart4trade.com/3.8/lib/python3.8/site-packages/django/db/models/manager.py", line 85, in manager_method
    return getattr(self.get_queryset(), name)(*args, **kwargs)
  File "/home/shivmarb/virtualenv/erp.mart4trade.com/3.8/lib/python3.8/site-packages/django/db/models/query.py", line 1249, in _insert
    return query.get_compiler(using=using).execute_sql(returning_fields)
  File "/home/shivmarb/virtualenv/erp.mart4trade.com/3.8/lib/python3.8/site-packages/django/db/models/sql/compiler.py", line 1394, in execute_sql
    for sql, params in self.as_sql():
  File "/home/shivmarb/virtualenv/erp.mart4trade.com/3.8/lib/python3.8/site-packages/django/db/models/sql/compiler.py", line 1337, in as_sql
    value_rows = [
  File "/home/shivmarb/virtualenv/erp.mart4trade.com/3.8/lib/python3.8/site-packages/django/db/models/sql/compiler.py", line 1338, in <listcomp>
    [self.prepare_value(field, self.pre_save_val(field, obj)) for field in fields]
  File "/home/shivmarb/virtualenv/erp.mart4trade.com/3.8/lib/python3.8/site-packages/django/db/models/sql/compiler.py", line 1338, in <listcomp>
    [self.prepare_value(field, self.pre_save_val(field, obj)) for field in fields]
  File "/home/shivmarb/virtualenv/erp.mart4trade.com/3.8/lib/python3.8/site-packages/django/db/models/sql/compiler.py", line 1279, in prepare_value
    value = field.get_db_prep_save(value, connection=self.connection)
  File "/home/shivmarb/virtualenv/erp.mart4trade.com/3.8/lib/python3.8/site-packages/django/db/models/fields/__init__.py", line 823, in get_db_prep_save
    return self.get_db_prep_value(value, connection=connection, prepared=False)
  File "/home/shivmarb/virtualenv/erp.mart4trade.com/3.8/lib/python3.8/site-packages/django/db/models/fields/__init__.py", line 818, in get_db_prep_value
    value = self.get_prep_value(value)
  File "/home/shivmarb/virtualenv/erp.mart4trade.com/3.8/lib/python3.8/site-packages/django/db/models/fields/__init__.py", line 967, in get_prep_value
    return self.to_python(value)
  File "/home/shivmarb/virtualenv/erp.mart4trade.com/3.8/lib/python3.8/site-packages/django/db/models/fields/__init__.py", line 957, in to_python
    raise exceptions.ValidationError(
django.core.exceptions.ValidationError: ['\u201con\u201d value must be either True, False, or None.']

During handling of the above exception, another exception occurred:

Traceback (most recent call last):
  File "/home/shivmarb/virtualenv/erp.mart4trade.com/3.8/lib/python3.8/site-packages/django/core/handlers/exception.py", line 47, in inner
    response = get_response(request)
  File "/home/shivmarb/virtualenv/erp.mart4trade.com/3.8/lib/python3.8/site-packages/django/core/handlers/base.py", line 179, in _get_response
    response = wrapped_callback(request, *callback_args, **callback_kwargs)
  File "/home/shivmarb/erp.mart4trade.com/martcrm/views.py", line 274, in create_company
    profile_obj = create_profile(request,**kwargs)
  File "/home/shivmarb/erp.mart4trade.com/martcrm/helper/register_profile.py", line 64, in create_profile
    print(f"There is come error {ex}")
UnicodeEncodeError: 'ascii' codec can't encode character '\u201c' in position 22: ordinal not in range(128)
Internal Server Error: /martcrm/create_company
Traceback (most recent call last):
  File "/home/shivmarb/erp.mart4trade.com/martcrm/helper/register_profile.py", line 22, in create_profile
    profile_obj = ProfileMaster.objects.create(
  File "/home/shivmarb/virtualenv/erp.mart4trade.com/3.8/lib/python3.8/site-packages/django/db/models/manager.py", line 85, in manager_method
    return getattr(self.get_queryset(), name)(*args, **kwargs)
  File "/home/shivmarb/virtualenv/erp.mart4trade.com/3.8/lib/python3.8/site-packages/django/db/models/query.py", line 447, in create
    obj.save(force_insert=True, using=self.db)
  File "/home/shivmarb/virtualenv/erp.mart4trade.com/3.8/lib/python3.8/site-packages/django/db/models/base.py", line 750, in save
    self.save_base(using=using, force_insert=force_insert,
  File "/home/shivmarb/virtualenv/erp.mart4trade.com/3.8/lib/python3.8/site-packages/django/db/models/base.py", line 787, in save_base
    updated = self._save_table(
  File "/home/shivmarb/virtualenv/erp.mart4trade.com/3.8/lib/python3.8/site-packages/django/db/models/base.py", line 892, in _save_table
    results = self._do_insert(cls._base_manager, using, fields, returning_fields, raw)
  File "/home/shivmarb/virtualenv/erp.mart4trade.com/3.8/lib/python3.8/site-packages/django/db/models/base.py", line 930, in _do_insert
    return manager._insert(
  File "/home/shivmarb/virtualenv/erp.mart4trade.com/3.8/lib/python3.8/site-packages/django/db/models/manager.py", line 85, in manager_method
    return getattr(self.get_queryset(), name)(*args, **kwargs)
  File "/home/shivmarb/virtualenv/erp.mart4trade.com/3.8/lib/python3.8/site-packages/django/db/models/query.py", line 1249, in _insert
    return query.get_compiler(using=using).execute_sql(returning_fields)
  File "/home/shivmarb/virtualenv/erp.mart4trade.com/3.8/lib/python3.8/site-packages/django/db/models/sql/compiler.py", line 1394, in execute_sql
    for sql, params in self.as_sql():
  File "/home/shivmarb/virtualenv/erp.mart4trade.com/3.8/lib/python3.8/site-packages/django/db/models/sql/compiler.py", line 1337, in as_sql
    value_rows = [
  File "/home/shivmarb/virtualenv/erp.mart4trade.com/3.8/lib/python3.8/site-packages/django/db/models/sql/compiler.py", line 1338, in <listcomp>
    [self.prepare_value(field, self.pre_save_val(field, obj)) for field in fields]
  File "/home/shivmarb/virtualenv/erp.mart4trade.com/3.8/lib/python3.8/site-packages/django/db/models/sql/compiler.py", line 1338, in <listcomp>
    [self.prepare_value(field, self.pre_save_val(field, obj)) for field in fields]
  File "/home/shivmarb/virtualenv/erp.mart4trade.com/3.8/lib/python3.8/site-packages/django/db/models/sql/compiler.py", line 1279, in prepare_value
    value = field.get_db_prep_save(value, connection=self.connection)
  File "/home/shivmarb/virtualenv/erp.mart4trade.com/3.8/lib/python3.8/site-packages/django/db/models/fields/__init__.py", line 823, in get_db_prep_save
    return self.get_db_prep_value(value, connection=connection, prepared=False)
  File "/home/shivmarb/virtualenv/erp.mart4trade.com/3.8/lib/python3.8/site-packages/django/db/models/fields/__init__.py", line 818, in get_db_prep_value
    value = self.get_prep_value(value)
  File "/home/shivmarb/virtualenv/erp.mart4trade.com/3.8/lib/python3.8/site-packages/django/db/models/fields/__init__.py", line 967, in get_prep_value
    return self.to_python(value)
  File "/home/shivmarb/virtualenv/erp.mart4trade.com/3.8/lib/python3.8/site-packages/django/db/models/fields/__init__.py", line 957, in to_python
    raise exceptions.ValidationError(
django.core.exceptions.ValidationError: ['\u201con\u201d value must be either True, False, or None.']

During handling of the above exception, another exception occurred:

Traceback (most recent call last):
  File "/home/shivmarb/virtualenv/erp.mart4trade.com/3.8/lib/python3.8/site-packages/django/core/handlers/exception.py", line 47, in inner
    response = get_response(request)
  File "/home/shivmarb/virtualenv/erp.mart4trade.com/3.8/lib/python3.8/site-packages/django/core/handlers/base.py", line 179, in _get_response
    response = wrapped_callback(request, *callback_args, **callback_kwargs)
  File "/home/shivmarb/erp.mart4trade.com/martcrm/views.py", line 274, in create_company
    profile_obj = create_profile(request,**kwargs)
  File "/home/shivmarb/erp.mart4trade.com/martcrm/helper/register_profile.py", line 64, in create_profile
    print(ex)
UnicodeEncodeError: 'ascii' codec can't encode character '\u201c' in position 2: ordinal not in range(128)
Email obj ====== EmailMaster object (8)
mobile_obj ====== MobileMaster object (8)
user_obj ====== UserAccounts object (8)
There is some error in company registration 'ascii' codec can't encode character '\u201c' in position 22: ordinal not in range(128)
Email obj ====== EmailMaster object (9)
mobile_obj ====== MobileMaster object (9)
user_obj ====== UserAccounts object (9)
There is some error in company registration 'ascii' codec can't encode character '\u201c' in position 2: ordinal not in range(128)
> /home/shivmarb/erp.mart4trade.com/martcrm/helper/register_profile.py(14)create_profile()
-> client_id = request.session.get('client_id')
(Pdb) Internal Server Error: /martcrm/create_company
Traceback (most recent call last):
  File "/home/shivmarb/virtualenv/erp.mart4trade.com/3.8/lib/python3.8/site-packages/django/core/handlers/exception.py", line 47, in inner
    response = get_response(request)
  File "/home/shivmarb/virtualenv/erp.mart4trade.com/3.8/lib/python3.8/site-packages/django/core/handlers/base.py", line 179, in _get_response
    response = wrapped_callback(request, *callback_args, **callback_kwargs)
  File "/home/shivmarb/erp.mart4trade.com/martcrm/views.py", line 274, in create_company
    profile_obj = create_profile(request,**kwargs)
  File "/home/shivmarb/erp.mart4trade.com/martcrm/helper/register_profile.py", line 14, in create_profile
    client_id = request.session.get('client_id')
  File "/home/shivmarb/erp.mart4trade.com/martcrm/helper/register_profile.py", line 14, in create_profile
    client_id = request.session.get('client_id')
  File "/opt/alt/python38/lib64/python3.8/bdb.py", line 88, in trace_dispatch
    return self.dispatch_line(frame)
  File "/opt/alt/python38/lib64/python3.8/bdb.py", line 113, in dispatch_line
    if self.quitting: raise BdbQuit
bdb.BdbQuit

There is some error in company registration 
> /home/shivmarb/erp.mart4trade.com/martcrm/helper/register_profile.py(14)create_profile()
-> client_id = request.session.get('client_id')
(Pdb) Internal Server Error: /martcrm/create_company
Traceback (most recent call last):
  File "/home/shivmarb/virtualenv/erp.mart4trade.com/3.8/lib/python3.8/site-packages/django/core/handlers/exception.py", line 47, in inner
    response = get_response(request)
  File "/home/shivmarb/virtualenv/erp.mart4trade.com/3.8/lib/python3.8/site-packages/django/core/handlers/base.py", line 179, in _get_response
    response = wrapped_callback(request, *callback_args, **callback_kwargs)
  File "/home/shivmarb/erp.mart4trade.com/martcrm/views.py", line 274, in create_company
    profile_obj = create_profile(request,**kwargs)
  File "/home/shivmarb/erp.mart4trade.com/martcrm/helper/register_profile.py", line 14, in create_profile
    client_id = request.session.get('client_id')
  File "/home/shivmarb/erp.mart4trade.com/martcrm/helper/register_profile.py", line 14, in create_profile
    client_id = request.session.get('client_id')
  File "/opt/alt/python38/lib64/python3.8/bdb.py", line 88, in trace_dispatch
    return self.dispatch_line(frame)
  File "/opt/alt/python38/lib64/python3.8/bdb.py", line 113, in dispatch_line
    if self.quitting: raise BdbQuit
bdb.BdbQuit

There is some error in company registration 
> /home/shivmarb/erp.mart4trade.com/martcrm/helper/register_profile.py(14)create_profile()
-> try:
(Pdb) Internal Server Error: /martcrm/create_company
Traceback (most recent call last):
  File "/home/shivmarb/virtualenv/erp.mart4trade.com/3.8/lib/python3.8/site-packages/django/core/handlers/exception.py", line 47, in inner
    response = get_response(request)
  File "/home/shivmarb/virtualenv/erp.mart4trade.com/3.8/lib/python3.8/site-packages/django/core/handlers/base.py", line 179, in _get_response
    response = wrapped_callback(request, *callback_args, **callback_kwargs)
  File "/home/shivmarb/erp.mart4trade.com/martcrm/views.py", line 274, in create_company
    profile_obj = create_profile(request,**kwargs)
  File "/home/shivmarb/erp.mart4trade.com/martcrm/helper/register_profile.py", line 14, in create_profile
    try:
  File "/home/shivmarb/erp.mart4trade.com/martcrm/helper/register_profile.py", line 14, in create_profile
    try:
  File "/opt/alt/python38/lib64/python3.8/bdb.py", line 88, in trace_dispatch
    return self.dispatch_line(frame)
  File "/opt/alt/python38/lib64/python3.8/bdb.py", line 113, in dispatch_line
    if self.quitting: raise BdbQuit
bdb.BdbQuit

There is some error in company registration 
> /home/shivmarb/erp.mart4trade.com/martcrm/helper/register_profile.py(14)create_profile()
-> try:
(Pdb) Internal Server Error: /martcrm/create_company
Traceback (most recent call last):
  File "/home/shivmarb/virtualenv/erp.mart4trade.com/3.8/lib/python3.8/site-packages/django/core/handlers/exception.py", line 47, in inner
    response = get_response(request)
  File "/home/shivmarb/virtualenv/erp.mart4trade.com/3.8/lib/python3.8/site-packages/django/core/handlers/base.py", line 179, in _get_response
    response = wrapped_callback(request, *callback_args, **callback_kwargs)
  File "/home/shivmarb/erp.mart4trade.com/martcrm/views.py", line 274, in create_company
    profile_obj = create_profile(request,**kwargs)
  File "/home/shivmarb/erp.mart4trade.com/martcrm/helper/register_profile.py", line 14, in create_profile
    try:
  File "/home/shivmarb/erp.mart4trade.com/martcrm/helper/register_profile.py", line 14, in create_profile
    try:
  File "/opt/alt/python38/lib64/python3.8/bdb.py", line 88, in trace_dispatch
    return self.dispatch_line(frame)
  File "/opt/alt/python38/lib64/python3.8/bdb.py", line 113, in dispatch_line
    if self.quitting: raise BdbQuit
bdb.BdbQuit

There is some error in company registration 
> /home/shivmarb/erp.mart4trade.com/martcrm/helper/register_profile.py(14)create_profile()
-> try:
(Pdb) Internal Server Error: /martcrm/create_company
Traceback (most recent call last):
  File "/home/shivmarb/virtualenv/erp.mart4trade.com/3.8/lib/python3.8/site-packages/django/core/handlers/exception.py", line 47, in inner
    response = get_response(request)
  File "/home/shivmarb/virtualenv/erp.mart4trade.com/3.8/lib/python3.8/site-packages/django/core/handlers/base.py", line 179, in _get_response
    response = wrapped_callback(request, *callback_args, **callback_kwargs)
  File "/home/shivmarb/erp.mart4trade.com/martcrm/views.py", line 274, in create_company
    profile_obj = create_profile(request,**kwargs)
  File "/home/shivmarb/erp.mart4trade.com/martcrm/helper/register_profile.py", line 14, in create_profile
    try:
  File "/home/shivmarb/erp.mart4trade.com/martcrm/helper/register_profile.py", line 14, in create_profile
    try:
  File "/opt/alt/python38/lib64/python3.8/bdb.py", line 88, in trace_dispatch
    return self.dispatch_line(frame)
  File "/opt/alt/python38/lib64/python3.8/bdb.py", line 113, in dispatch_line
    if self.quitting: raise BdbQuit
bdb.BdbQuit

There is some error in company registration 
> /home/shivmarb/erp.mart4trade.com/martcrm/helper/register_profile.py(14)create_profile()
-> try:
(Pdb) Internal Server Error: /martcrm/create_company
Traceback (most recent call last):
  File "/home/shivmarb/virtualenv/erp.mart4trade.com/3.8/lib/python3.8/site-packages/django/core/handlers/exception.py", line 47, in inner
    response = get_response(request)
  File "/home/shivmarb/virtualenv/erp.mart4trade.com/3.8/lib/python3.8/site-packages/django/core/handlers/base.py", line 179, in _get_response
    response = wrapped_callback(request, *callback_args, **callback_kwargs)
  File "/home/shivmarb/erp.mart4trade.com/martcrm/views.py", line 274, in create_company
    profile_obj = create_profile(request,**kwargs)
  File "/home/shivmarb/erp.mart4trade.com/martcrm/helper/register_profile.py", line 14, in create_profile
    try:
  File "/home/shivmarb/erp.mart4trade.com/martcrm/helper/register_profile.py", line 14, in create_profile
    try:
  File "/opt/alt/python38/lib64/python3.8/bdb.py", line 88, in trace_dispatch
    return self.dispatch_line(frame)
  File "/opt/alt/python38/lib64/python3.8/bdb.py", line 113, in dispatch_line
    if self.quitting: raise BdbQuit
bdb.BdbQuit
Not Found: /martcrm/assets/img/logo.png
Not Found: /martcrm/assets/img/messages-1.jpg
Not Found: /martcrm/assets/img/messages-2.jpg
Not Found: /martcrm/assets/img/messages-3.jpg
Not Found: /martcrm/assets/img/profile-img.jpg
Internal Server Error: /martcrm/create_company
Traceback (most recent call last):
  File "/home/shivmarb/erp.mart4trade.com/martcrm/helper/register_profile.py", line 22, in create_profile
    profile_obj = ProfileMaster.objects.create(
  File "/home/shivmarb/virtualenv/erp.mart4trade.com/3.8/lib/python3.8/site-packages/django/db/models/manager.py", line 85, in manager_method
    return getattr(self.get_queryset(), name)(*args, **kwargs)
  File "/home/shivmarb/virtualenv/erp.mart4trade.com/3.8/lib/python3.8/site-packages/django/db/models/query.py", line 447, in create
    obj.save(force_insert=True, using=self.db)
  File "/home/shivmarb/virtualenv/erp.mart4trade.com/3.8/lib/python3.8/site-packages/django/db/models/base.py", line 750, in save
    self.save_base(using=using, force_insert=force_insert,
  File "/home/shivmarb/virtualenv/erp.mart4trade.com/3.8/lib/python3.8/site-packages/django/db/models/base.py", line 787, in save_base
    updated = self._save_table(
  File "/home/shivmarb/virtualenv/erp.mart4trade.com/3.8/lib/python3.8/site-packages/django/db/models/base.py", line 892, in _save_table
    results = self._do_insert(cls._base_manager, using, fields, returning_fields, raw)
  File "/home/shivmarb/virtualenv/erp.mart4trade.com/3.8/lib/python3.8/site-packages/django/db/models/base.py", line 930, in _do_insert
    return manager._insert(
  File "/home/shivmarb/virtualenv/erp.mart4trade.com/3.8/lib/python3.8/site-packages/django/db/models/manager.py", line 85, in manager_method
    return getattr(self.get_queryset(), name)(*args, **kwargs)
  File "/home/shivmarb/virtualenv/erp.mart4trade.com/3.8/lib/python3.8/site-packages/django/db/models/query.py", line 1249, in _insert
    return query.get_compiler(using=using).execute_sql(returning_fields)
  File "/home/shivmarb/virtualenv/erp.mart4trade.com/3.8/lib/python3.8/site-packages/django/db/models/sql/compiler.py", line 1394, in execute_sql
    for sql, params in self.as_sql():
  File "/home/shivmarb/virtualenv/erp.mart4trade.com/3.8/lib/python3.8/site-packages/django/db/models/sql/compiler.py", line 1337, in as_sql
    value_rows = [
  File "/home/shivmarb/virtualenv/erp.mart4trade.com/3.8/lib/python3.8/site-packages/django/db/models/sql/compiler.py", line 1338, in <listcomp>
    [self.prepare_value(field, self.pre_save_val(field, obj)) for field in fields]
  File "/home/shivmarb/virtualenv/erp.mart4trade.com/3.8/lib/python3.8/site-packages/django/db/models/sql/compiler.py", line 1338, in <listcomp>
    [self.prepare_value(field, self.pre_save_val(field, obj)) for field in fields]
  File "/home/shivmarb/virtualenv/erp.mart4trade.com/3.8/lib/python3.8/site-packages/django/db/models/sql/compiler.py", line 1279, in prepare_value
    value = field.get_db_prep_save(value, connection=self.connection)
  File "/home/shivmarb/virtualenv/erp.mart4trade.com/3.8/lib/python3.8/site-packages/django/db/models/fields/__init__.py", line 823, in get_db_prep_save
    return self.get_db_prep_value(value, connection=connection, prepared=False)
  File "/home/shivmarb/virtualenv/erp.mart4trade.com/3.8/lib/python3.8/site-packages/django/db/models/fields/__init__.py", line 818, in get_db_prep_value
    value = self.get_prep_value(value)
  File "/home/shivmarb/virtualenv/erp.mart4trade.com/3.8/lib/python3.8/site-packages/django/db/models/fields/__init__.py", line 967, in get_prep_value
    return self.to_python(value)
  File "/home/shivmarb/virtualenv/erp.mart4trade.com/3.8/lib/python3.8/site-packages/django/db/models/fields/__init__.py", line 957, in to_python
    raise exceptions.ValidationError(
django.core.exceptions.ValidationError: ['\u201con\u201d value must be either True, False, or None.']

During handling of the above exception, another exception occurred:

Traceback (most recent call last):
  File "/home/shivmarb/virtualenv/erp.mart4trade.com/3.8/lib/python3.8/site-packages/django/core/handlers/exception.py", line 47, in inner
    response = get_response(request)
  File "/home/shivmarb/virtualenv/erp.mart4trade.com/3.8/lib/python3.8/site-packages/django/core/handlers/base.py", line 179, in _get_response
    response = wrapped_callback(request, *callback_args, **callback_kwargs)
  File "/home/shivmarb/erp.mart4trade.com/martcrm/views.py", line 274, in create_company
    profile_obj = create_profile(request,**kwargs)
  File "/home/shivmarb/erp.mart4trade.com/martcrm/helper/register_profile.py", line 64, in create_profile
    print(ex)
UnicodeEncodeError: 'ascii' codec can't encode character '\u201c' in position 2: ordinal not in range(128)

There is some error in company registration 
Email obj ====== EmailMaster object (10)
mobile_obj ====== MobileMaster object (10)
user_obj ====== UserAccounts object (10)
There is some error in company registration 'ascii' codec can't encode character '\u201c' in position 2: ordinal not in range(128)
Internal Server Error: /martcrm/create_company
Traceback (most recent call last):
  File "/home/shivmarb/erp.mart4trade.com/martcrm/helper/register_profile.py", line 22, in create_profile
    profile_obj = ProfileMaster.objects.create(
  File "/home/shivmarb/virtualenv/erp.mart4trade.com/3.8/lib/python3.8/site-packages/django/db/models/manager.py", line 85, in manager_method
    return getattr(self.get_queryset(), name)(*args, **kwargs)
  File "/home/shivmarb/virtualenv/erp.mart4trade.com/3.8/lib/python3.8/site-packages/django/db/models/query.py", line 447, in create
    obj.save(force_insert=True, using=self.db)
  File "/home/shivmarb/virtualenv/erp.mart4trade.com/3.8/lib/python3.8/site-packages/django/db/models/base.py", line 750, in save
    self.save_base(using=using, force_insert=force_insert,
  File "/home/shivmarb/virtualenv/erp.mart4trade.com/3.8/lib/python3.8/site-packages/django/db/models/base.py", line 787, in save_base
    updated = self._save_table(
  File "/home/shivmarb/virtualenv/erp.mart4trade.com/3.8/lib/python3.8/site-packages/django/db/models/base.py", line 892, in _save_table
    results = self._do_insert(cls._base_manager, using, fields, returning_fields, raw)
  File "/home/shivmarb/virtualenv/erp.mart4trade.com/3.8/lib/python3.8/site-packages/django/db/models/base.py", line 930, in _do_insert
    return manager._insert(
  File "/home/shivmarb/virtualenv/erp.mart4trade.com/3.8/lib/python3.8/site-packages/django/db/models/manager.py", line 85, in manager_method
    return getattr(self.get_queryset(), name)(*args, **kwargs)
  File "/home/shivmarb/virtualenv/erp.mart4trade.com/3.8/lib/python3.8/site-packages/django/db/models/query.py", line 1249, in _insert
    return query.get_compiler(using=using).execute_sql(returning_fields)
  File "/home/shivmarb/virtualenv/erp.mart4trade.com/3.8/lib/python3.8/site-packages/django/db/models/sql/compiler.py", line 1394, in execute_sql
    for sql, params in self.as_sql():
  File "/home/shivmarb/virtualenv/erp.mart4trade.com/3.8/lib/python3.8/site-packages/django/db/models/sql/compiler.py", line 1337, in as_sql
    value_rows = [
  File "/home/shivmarb/virtualenv/erp.mart4trade.com/3.8/lib/python3.8/site-packages/django/db/models/sql/compiler.py", line 1338, in <listcomp>
    [self.prepare_value(field, self.pre_save_val(field, obj)) for field in fields]
  File "/home/shivmarb/virtualenv/erp.mart4trade.com/3.8/lib/python3.8/site-packages/django/db/models/sql/compiler.py", line 1338, in <listcomp>
    [self.prepare_value(field, self.pre_save_val(field, obj)) for field in fields]
  File "/home/shivmarb/virtualenv/erp.mart4trade.com/3.8/lib/python3.8/site-packages/django/db/models/sql/compiler.py", line 1279, in prepare_value
    value = field.get_db_prep_save(value, connection=self.connection)
  File "/home/shivmarb/virtualenv/erp.mart4trade.com/3.8/lib/python3.8/site-packages/django/db/models/fields/__init__.py", line 823, in get_db_prep_save
    return self.get_db_prep_value(value, connection=connection, prepared=False)
  File "/home/shivmarb/virtualenv/erp.mart4trade.com/3.8/lib/python3.8/site-packages/django/db/models/fields/__init__.py", line 818, in get_db_prep_value
    value = self.get_prep_value(value)
  File "/home/shivmarb/virtualenv/erp.mart4trade.com/3.8/lib/python3.8/site-packages/django/db/models/fields/__init__.py", line 967, in get_prep_value
    return self.to_python(value)
  File "/home/shivmarb/virtualenv/erp.mart4trade.com/3.8/lib/python3.8/site-packages/django/db/models/fields/__init__.py", line 957, in to_python
    raise exceptions.ValidationError(
django.core.exceptions.ValidationError: ['\u201con\u201d value must be either True, False, or None.']

During handling of the above exception, another exception occurred:

Traceback (most recent call last):
  File "/home/shivmarb/virtualenv/erp.mart4trade.com/3.8/lib/python3.8/site-packages/django/core/handlers/exception.py", line 47, in inner
    response = get_response(request)
  File "/home/shivmarb/virtualenv/erp.mart4trade.com/3.8/lib/python3.8/site-packages/django/core/handlers/base.py", line 179, in _get_response
    response = wrapped_callback(request, *callback_args, **callback_kwargs)
  File "/home/shivmarb/erp.mart4trade.com/martcrm/views.py", line 274, in create_company
    profile_obj = create_profile(request,**kwargs)
  File "/home/shivmarb/erp.mart4trade.com/martcrm/helper/register_profile.py", line 64, in create_profile
    print(ex)
UnicodeEncodeError: 'ascii' codec can't encode character '\u201c' in position 2: ordinal not in range(128)
Internal Server Error: /martcrm/create_company
Traceback (most recent call last):
  File "/home/shivmarb/virtualenv/erp.mart4trade.com/3.8/lib/python3.8/site-packages/django/core/handlers/exception.py", line 47, in inner
    response = get_response(request)
  File "/home/shivmarb/virtualenv/erp.mart4trade.com/3.8/lib/python3.8/site-packages/django/core/handlers/base.py", line 179, in _get_response
    response = wrapped_callback(request, *callback_args, **callback_kwargs)
  File "/home/shivmarb/erp.mart4trade.com/martcrm/views.py", line 274, in create_company
    profile_obj = create_profile(request,**kwargs)
  File "/home/shivmarb/erp.mart4trade.com/martcrm/helper/register_profile.py", line 58, in create_profile
    acc_email_obj = AccountEmails.objects.create(userid=userid, email_key=email_key)
  File "/home/shivmarb/virtualenv/erp.mart4trade.com/3.8/lib/python3.8/site-packages/django/db/models/manager.py", line 85, in manager_method
    return getattr(self.get_queryset(), name)(*args, **kwargs)
  File "/home/shivmarb/virtualenv/erp.mart4trade.com/3.8/lib/python3.8/site-packages/django/db/models/query.py", line 445, in create
    obj = self.model(**kwargs)
  File "/home/shivmarb/virtualenv/erp.mart4trade.com/3.8/lib/python3.8/site-packages/django/db/models/base.py", line 483, in __init__
    _setattr(self, field.name, rel_obj)
  File "/home/shivmarb/virtualenv/erp.mart4trade.com/3.8/lib/python3.8/site-packages/django/db/models/fields/related_descriptors.py", line 215, in __set__
    raise ValueError(
ValueError: Cannot assign "12": "AccountEmails.userid" must be a "UserAccounts" instance.
Email obj ====== EmailMaster object (11)
mobile_obj ====== MobileMaster object (11)
user_obj ====== UserAccounts object (11)
There is some error in company registration 'ascii' codec can't encode character '\u201c' in position 2: ordinal not in range(128)
Email obj ====== EmailMaster object (12)
mobile_obj ====== MobileMaster object (12)
user_obj ====== UserAccounts object (12)
Profile obj ==  ProfileMaster object (1)
email_key ==  12
mobile_key ==  12
Cannot assign "12": "AccountEmails.userid" must be a "UserAccounts" instance.
There is some error in company registration Cannot assign "12": "AccountEmails.userid" must be a "UserAccounts" instance.
Cannot assign "13": "AccountEmails.email_key" must be a "EmailMaster" instance.
There is some error in company registration Cannot assign "13": "AccountEmails.email_key" must be a "EmailMaster" instance.
Cannot assign "14": "AccountEmails.email_key" must be a "EmailMaster" instance.
There is some error in company registration Cannot assign "14": "AccountEmails.email_key" must be a "EmailMaster" instance.
Cannot assign "15": "AccountEmails.email_key" must be a "EmailMaster" instance.
There is some error in company registration Cannot assign "15": "AccountEmails.email_key" must be a "EmailMaster" instance.
Cannot assign "16": "AccountEmails.email_key" must be a "EmailMaster" instance.
There is some error in company registration Cannot assign "16": "AccountEmails.email_key" must be a "EmailMaster" instance.
Cannot assign "17": "AccountEmails.email_key" must be a "EmailMaster" instance.
There is some error in company registration Cannot assign "17": "AccountEmails.email_key" must be a "EmailMaster" instance.
Cannot assign "18": "AccountEmails.email_key" must be a "EmailMaster" instance.
There is some error in company registration Cannot assign "18": "AccountEmails.email_key" must be a "EmailMaster" instance.
Cannot assign "19": "AccountEmails.email_key" must be a "EmailMaster" instance.
There is some error in company registration Cannot assign "19": "AccountEmails.email_key" must be a "EmailMaster" instance.
Cannot assign "20": "AccountEmails.email_key" must be a "EmailMaster" instance.
There is some error in company registration Cannot assign "20": "AccountEmails.email_key" must be a "EmailMaster" instance.
Cannot assign "21": "AccountEmails.email_key" must be a "EmailMaster" instance.
There is some error in company registration Cannot assign "21": "AccountEmails.email_key" must be a "EmailMaster" instance.
Cannot assign "22": "AccountEmails.email_key" must be a "EmailMaster" instance.
There is some error in company registration Cannot assign "22": "AccountEmails.email_key" must be a "EmailMaster" instance.
Cannot assign "23": "AccountEmails.email_key" must be a "EmailMaster" instance.
There is some error in company registration Cannot assign "23": "AccountEmails.email_key" must be a "EmailMaster" instance.
Cannot assign "24": "AccountEmails.email_key" must be a "EmailMaster" instance.
There is some error in company registration Cannot assign "24": "AccountEmails.email_key" must be a "EmailMaster" instance.
Cannot assign "25": "AccountEmails.email_key" must be a "EmailMaster" instance.
There is some error in company registration Cannot assign "25": "AccountEmails.email_key" must be a "EmailMaster" instance.
Cannot assign "26": "AccountEmails.email_key" must be a "EmailMaster" instance.
There is some error in company registration Cannot assign "26": "AccountEmails.email_key" must be a "EmailMaster" instance.
Cannot assign "27": "AccountEmails.email_key" must be a "EmailMaster" instance.
There is some error in company registration Cannot assign "27": "AccountEmails.email_key" must be a "EmailMaster" instance.
Cannot assign "28": "AccountEmails.email_key" must be a "EmailMaster" instance.
There is some error in company registration Cannot assign "28": "AccountEmails.email_key" must be a "EmailMaster" instance.
Cannot assign "29": "AccountEmails.email_key" must be a "EmailMaster" instance.
There is some error in company registration Cannot assign "29": "AccountEmails.email_key" must be a "EmailMaster" instance.
Internal Server Error: /martcrm/create_company
Traceback (most recent call last):
  File "/home/shivmarb/virtualenv/erp.mart4trade.com/3.8/lib/python3.8/site-packages/django/core/handlers/exception.py", line 47, in inner
    response = get_response(request)
  File "/home/shivmarb/virtualenv/erp.mart4trade.com/3.8/lib/python3.8/site-packages/django/core/handlers/base.py", line 179, in _get_response
    response = wrapped_callback(request, *callback_args, **callback_kwargs)
  File "/home/shivmarb/erp.mart4trade.com/martcrm/views.py", line 274, in create_company
    profile_obj = create_profile(request,**kwargs)
  File "/home/shivmarb/erp.mart4trade.com/martcrm/helper/register_profile.py", line 58, in create_profile
    acc_email_obj = AccountEmails.objects.create(userid=userid, email_key=email_key)
  File "/home/shivmarb/virtualenv/erp.mart4trade.com/3.8/lib/python3.8/site-packages/django/db/models/manager.py", line 85, in manager_method
    return getattr(self.get_queryset(), name)(*args, **kwargs)
  File "/home/shivmarb/virtualenv/erp.mart4trade.com/3.8/lib/python3.8/site-packages/django/db/models/query.py", line 445, in create
    obj = self.model(**kwargs)
  File "/home/shivmarb/virtualenv/erp.mart4trade.com/3.8/lib/python3.8/site-packages/django/db/models/base.py", line 483, in __init__
    _setattr(self, field.name, rel_obj)
  File "/home/shivmarb/virtualenv/erp.mart4trade.com/3.8/lib/python3.8/site-packages/django/db/models/fields/related_descriptors.py", line 215, in __set__
    raise ValueError(
ValueError: Cannot assign "30": "AccountEmails.userid" must be a "UserAccounts" instance.
Internal Server Error: /martcrm/create_company
Traceback (most recent call last):
  File "/home/shivmarb/virtualenv/erp.mart4trade.com/3.8/lib/python3.8/site-packages/django/core/handlers/exception.py", line 47, in inner
    response = get_response(request)
  File "/home/shivmarb/virtualenv/erp.mart4trade.com/3.8/lib/python3.8/site-packages/django/core/handlers/base.py", line 179, in _get_response
    response = wrapped_callback(request, *callback_args, **callback_kwargs)
  File "/home/shivmarb/erp.mart4trade.com/martcrm/views.py", line 274, in create_company
    profile_obj = create_profile(request,**kwargs)
  File "/home/shivmarb/erp.mart4trade.com/martcrm/helper/register_profile.py", line 58, in create_profile
    profile_id = profile_obj.profile_id
  File "/home/shivmarb/virtualenv/erp.mart4trade.com/3.8/lib/python3.8/site-packages/django/db/models/manager.py", line 85, in manager_method
    return getattr(self.get_queryset(), name)(*args, **kwargs)
  File "/home/shivmarb/virtualenv/erp.mart4trade.com/3.8/lib/python3.8/site-packages/django/db/models/query.py", line 445, in create
    obj = self.model(**kwargs)
  File "/home/shivmarb/virtualenv/erp.mart4trade.com/3.8/lib/python3.8/site-packages/django/db/models/base.py", line 483, in __init__
    _setattr(self, field.name, rel_obj)
  File "/home/shivmarb/virtualenv/erp.mart4trade.com/3.8/lib/python3.8/site-packages/django/db/models/fields/related_descriptors.py", line 215, in __set__
    raise ValueError(
ValueError: Cannot assign "31": "AccountEmails.userid" must be a "UserAccounts" instance.
Internal Server Error: /martcrm/create_company
Traceback (most recent call last):
  File "/home/shivmarb/virtualenv/erp.mart4trade.com/3.8/lib/python3.8/site-packages/django/core/handlers/exception.py", line 47, in inner
    response = get_response(request)
  File "/home/shivmarb/virtualenv/erp.mart4trade.com/3.8/lib/python3.8/site-packages/django/core/handlers/base.py", line 179, in _get_response
    response = wrapped_callback(request, *callback_args, **callback_kwargs)
  File "/home/shivmarb/erp.mart4trade.com/martcrm/views.py", line 274, in create_company
    profile_obj = create_profile(request,**kwargs)
  File "/home/shivmarb/erp.mart4trade.com/martcrm/helper/register_profile.py", line 58, in create_profile
    profile_id = profile_obj.profile_id
  File "/home/shivmarb/virtualenv/erp.mart4trade.com/3.8/lib/python3.8/site-packages/django/db/models/manager.py", line 85, in manager_method
    return getattr(self.get_queryset(), name)(*args, **kwargs)
  File "/home/shivmarb/virtualenv/erp.mart4trade.com/3.8/lib/python3.8/site-packages/django/db/models/query.py", line 445, in create
    obj = self.model(**kwargs)
  File "/home/shivmarb/virtualenv/erp.mart4trade.com/3.8/lib/python3.8/site-packages/django/db/models/base.py", line 483, in __init__
    _setattr(self, field.name, rel_obj)
  File "/home/shivmarb/virtualenv/erp.mart4trade.com/3.8/lib/python3.8/site-packages/django/db/models/fields/related_descriptors.py", line 215, in __set__
    raise ValueError(
ValueError: Cannot assign "32": "AccountEmails.userid" must be a "UserAccounts" instance.
Internal Server Error: /martcrm/create_company
Traceback (most recent call last):
  File "/home/shivmarb/virtualenv/erp.mart4trade.com/3.8/lib/python3.8/site-packages/django/core/handlers/exception.py", line 47, in inner
    response = get_response(request)
  File "/home/shivmarb/virtualenv/erp.mart4trade.com/3.8/lib/python3.8/site-packages/django/core/handlers/base.py", line 179, in _get_response
    response = wrapped_callback(request, *callback_args, **callback_kwargs)
  File "/home/shivmarb/erp.mart4trade.com/martcrm/views.py", line 274, in create_company
    profile_obj = create_profile(request,**kwargs)
  File "/home/shivmarb/erp.mart4trade.com/martcrm/helper/register_profile.py", line 58, in create_profile
    profile_id = profile_obj.profile_id
  File "/home/shivmarb/virtualenv/erp.mart4trade.com/3.8/lib/python3.8/site-packages/django/db/models/manager.py", line 85, in manager_method
    return getattr(self.get_queryset(), name)(*args, **kwargs)
  File "/home/shivmarb/virtualenv/erp.mart4trade.com/3.8/lib/python3.8/site-packages/django/db/models/query.py", line 445, in create
    obj = self.model(**kwargs)
  File "/home/shivmarb/virtualenv/erp.mart4trade.com/3.8/lib/python3.8/site-packages/django/db/models/base.py", line 483, in __init__
    _setattr(self, field.name, rel_obj)
  File "/home/shivmarb/virtualenv/erp.mart4trade.com/3.8/lib/python3.8/site-packages/django/db/models/fields/related_descriptors.py", line 215, in __set__
    raise ValueError(
ValueError: Cannot assign "33": "AccountEmails.userid" must be a "UserAccounts" instance.
Internal Server Error: /martcrm/create_company
Traceback (most recent call last):
  File "/home/shivmarb/virtualenv/erp.mart4trade.com/3.8/lib/python3.8/site-packages/django/core/handlers/exception.py", line 47, in inner
    response = get_response(request)
  File "/home/shivmarb/virtualenv/erp.mart4trade.com/3.8/lib/python3.8/site-packages/django/core/handlers/base.py", line 179, in _get_response
    response = wrapped_callback(request, *callback_args, **callback_kwargs)
  File "/home/shivmarb/erp.mart4trade.com/martcrm/views.py", line 274, in create_company
    profile_obj = create_profile(request,**kwargs)
  File "/home/shivmarb/erp.mart4trade.com/martcrm/helper/register_profile.py", line 59, in create_profile
    acc_email_obj = AccountEmails.objects.create(userid=user_obj.userid, email_key=email_key)
  File "/home/shivmarb/virtualenv/erp.mart4trade.com/3.8/lib/python3.8/site-packages/django/db/models/manager.py", line 85, in manager_method
    return getattr(self.get_queryset(), name)(*args, **kwargs)
  File "/home/shivmarb/virtualenv/erp.mart4trade.com/3.8/lib/python3.8/site-packages/django/db/models/query.py", line 445, in create
    obj = self.model(**kwargs)
  File "/home/shivmarb/virtualenv/erp.mart4trade.com/3.8/lib/python3.8/site-packages/django/db/models/base.py", line 483, in __init__
    _setattr(self, field.name, rel_obj)
  File "/home/shivmarb/virtualenv/erp.mart4trade.com/3.8/lib/python3.8/site-packages/django/db/models/fields/related_descriptors.py", line 215, in __set__
    raise ValueError(
ValueError: Cannot assign "34": "AccountEmails.userid" must be a "UserAccounts" instance.
Not Found: /favicon.ico
Internal Server Error: /martcrm/create_company
Traceback (most recent call last):
  File "/home/shivmarb/virtualenv/erp.mart4trade.com/3.8/lib/python3.8/site-packages/django/core/handlers/exception.py", line 47, in inner
    response = get_response(request)
  File "/home/shivmarb/virtualenv/erp.mart4trade.com/3.8/lib/python3.8/site-packages/django/core/handlers/base.py", line 179, in _get_response
    response = wrapped_callback(request, *callback_args, **callback_kwargs)
  File "/home/shivmarb/erp.mart4trade.com/martcrm/views.py", line 274, in create_company
    profile_obj = create_profile(request,**kwargs)
  File "/home/shivmarb/erp.mart4trade.com/martcrm/helper/register_profile.py", line 59, in create_profile
    acc_email_obj = AccountEmails.objects.create(userid=user_obj.userid, email_key=email_key)
  File "/home/shivmarb/virtualenv/erp.mart4trade.com/3.8/lib/python3.8/site-packages/django/db/models/manager.py", line 85, in manager_method
    return getattr(self.get_queryset(), name)(*args, **kwargs)
  File "/home/shivmarb/virtualenv/erp.mart4trade.com/3.8/lib/python3.8/site-packages/django/db/models/query.py", line 445, in create
    obj = self.model(**kwargs)
  File "/home/shivmarb/virtualenv/erp.mart4trade.com/3.8/lib/python3.8/site-packages/django/db/models/base.py", line 483, in __init__
    _setattr(self, field.name, rel_obj)
  File "/home/shivmarb/virtualenv/erp.mart4trade.com/3.8/lib/python3.8/site-packages/django/db/models/fields/related_descriptors.py", line 215, in __set__
    raise ValueError(
ValueError: Cannot assign "35": "AccountEmails.userid" must be a "UserAccounts" instance.
Internal Server Error: /martcrm/create_company
Traceback (most recent call last):
  File "/home/shivmarb/virtualenv/erp.mart4trade.com/3.8/lib/python3.8/site-packages/django/core/handlers/exception.py", line 47, in inner
    response = get_response(request)
  File "/home/shivmarb/virtualenv/erp.mart4trade.com/3.8/lib/python3.8/site-packages/django/core/handlers/base.py", line 179, in _get_response
    response = wrapped_callback(request, *callback_args, **callback_kwargs)
  File "/home/shivmarb/erp.mart4trade.com/martcrm/views.py", line 274, in create_company
    profile_obj = create_profile(request,**kwargs)
  File "/home/shivmarb/erp.mart4trade.com/martcrm/helper/register_profile.py", line 59, in create_profile
    acc_email_obj = AccountEmails.objects.create(userid=user_obj.userid, email_key=email_key)
  File "/home/shivmarb/virtualenv/erp.mart4trade.com/3.8/lib/python3.8/site-packages/django/db/models/manager.py", line 85, in manager_method
    return getattr(self.get_queryset(), name)(*args, **kwargs)
  File "/home/shivmarb/virtualenv/erp.mart4trade.com/3.8/lib/python3.8/site-packages/django/db/models/query.py", line 445, in create
    obj = self.model(**kwargs)
  File "/home/shivmarb/virtualenv/erp.mart4trade.com/3.8/lib/python3.8/site-packages/django/db/models/base.py", line 483, in __init__
    _setattr(self, field.name, rel_obj)
  File "/home/shivmarb/virtualenv/erp.mart4trade.com/3.8/lib/python3.8/site-packages/django/db/models/fields/related_descriptors.py", line 215, in __set__
    raise ValueError(
ValueError: Cannot assign "36": "AccountEmails.userid" must be a "UserAccounts" instance.
Internal Server Error: /martcrm/create_company
Traceback (most recent call last):
  File "/home/shivmarb/virtualenv/erp.mart4trade.com/3.8/lib/python3.8/site-packages/django/core/handlers/exception.py", line 47, in inner
    response = get_response(request)
  File "/home/shivmarb/virtualenv/erp.mart4trade.com/3.8/lib/python3.8/site-packages/django/core/handlers/base.py", line 179, in _get_response
    response = wrapped_callback(request, *callback_args, **callback_kwargs)
  File "/home/shivmarb/erp.mart4trade.com/martcrm/views.py", line 274, in create_company
    profile_obj = create_profile(request,**kwargs)
  File "/home/shivmarb/erp.mart4trade.com/martcrm/helper/register_profile.py", line 59, in create_profile
    acc_email_obj = AccountEmails.objects.create(userid=user_obj.userid, email_key=email_key)
  File "/home/shivmarb/virtualenv/erp.mart4trade.com/3.8/lib/python3.8/site-packages/django/db/models/manager.py", line 85, in manager_method
    return getattr(self.get_queryset(), name)(*args, **kwargs)
  File "/home/shivmarb/virtualenv/erp.mart4trade.com/3.8/lib/python3.8/site-packages/django/db/models/query.py", line 445, in create
    obj = self.model(**kwargs)
  File "/home/shivmarb/virtualenv/erp.mart4trade.com/3.8/lib/python3.8/site-packages/django/db/models/base.py", line 483, in __init__
    _setattr(self, field.name, rel_obj)
  File "/home/shivmarb/virtualenv/erp.mart4trade.com/3.8/lib/python3.8/site-packages/django/db/models/fields/related_descriptors.py", line 215, in __set__
    raise ValueError(
ValueError: Cannot assign "37": "AccountEmails.userid" must be a "UserAccounts" instance.
Not Found: /favicon.ico
Email obj ====== EmailMaster object (35)
mobile_obj ====== MobileMaster object (35)
user_obj ====== {'_state': <django.db.models.base.ModelState object at 0x7f6d29060d90>, 'userid': 35, 'username': 'shaileshgola', 'password': 'rahul123!@#', 'title': None, 'fname': 'Shailesh', 'mname': '', 'lname': 'KUMAR', 'desg': 'Software Developer', 'creation_date': None, 'creation_time': None, 'last_visit': None, 'activation_code': None, 'auto_registered': None, 'buy_inquiry': None, 'sell_inquiry': None, 'webmail_status': '', 'account_status': '', 'section_id': None, 'heard_from': None, 'sms_balance': None, 'last_visit_time': None, 'id_verified': None, 'unmoderated_inq': None, 'tradealert_del_pref': None, 'terms_accepted': None, 'inq_orig_pref': None, 'generated_e': None, 'roaming_access': None, 'last_password_change': None, 'buy_rfis_limit': None, 'pw_hash': '', 'password_uncr': None, 'rfis_rate': None, 'avg_rfis_resp_time': None, 'show_rfis_rate': None, 'buyer_feedback': None, 'show_buyer_feedback': None, 'hide_rfis_rate': None, 'hide_buyer_feedback': None, 'inq_to_all_users': None, 'mark_inquiry_cc': None, 'user_image': None, 'miss_call_alert': None, 'merchant_account_id': None, 'google_tnc_accepted': None, 'google_ads_account_id': None, 'is_gmc_link_with_ads': None, 'adhaar_no': None, 'username_hi': None, 'desg_hi': None}
Profile obj ==  ProfileMaster object (24)
email_key ==  35
mobile_key ==  35
user_obj ==== UserAccounts object (35)
Cannot assign "35": "AccountEmails.userid" must be a "UserAccounts" instance.
There is some error in company registration Cannot assign "35": "AccountEmails.userid" must be a "UserAccounts" instance.
Email obj ====== EmailMaster object (36)
mobile_obj ====== MobileMaster object (36)
user_obj ====== {'_state': <django.db.models.base.ModelState object at 0x7f6d29041670>, 'userid': 36, 'username': 'shaileshgola', 'password': 'rahul123!@#', 'title': None, 'fname': 'Shailesh', 'mname': '', 'lname': 'KUMAR', 'desg': 'Software Developer', 'creation_date': None, 'creation_time': None, 'last_visit': None, 'activation_code': None, 'auto_registered': None, 'buy_inquiry': None, 'sell_inquiry': None, 'webmail_status': '', 'account_status': '', 'section_id': None, 'heard_from': None, 'sms_balance': None, 'last_visit_time': None, 'id_verified': None, 'unmoderated_inq': None, 'tradealert_del_pref': None, 'terms_accepted': None, 'inq_orig_pref': None, 'generated_e': None, 'roaming_access': None, 'last_password_change': None, 'buy_rfis_limit': None, 'pw_hash': '', 'password_uncr': None, 'rfis_rate': None, 'avg_rfis_resp_time': None, 'show_rfis_rate': None, 'buyer_feedback': None, 'show_buyer_feedback': None, 'hide_rfis_rate': None, 'hide_buyer_feedback': None, 'inq_to_all_users': None, 'mark_inquiry_cc': None, 'user_image': None, 'miss_call_alert': None, 'merchant_account_id': None, 'google_tnc_accepted': None, 'google_ads_account_id': None, 'is_gmc_link_with_ads': None, 'adhaar_no': None, 'username_hi': None, 'desg_hi': None}
Profile obj ==  ProfileMaster object (25)
email_key ==  36
mobile_key ==  36
user_obj ==== UserAccounts object (36)
Cannot assign "36": "AccountEmails.userid" must be a "UserAccounts" instance.
There is some error in company registration Cannot assign "36": "AccountEmails.userid" must be a "UserAccounts" instance.
Email obj ====== EmailMaster object (37)
mobile_obj ====== MobileMaster object (37)
user_obj ====== {'_state': <django.db.models.base.ModelState object at 0x7f6d28fd62e0>, 'userid': 37, 'username': 'shaileshgola', 'password': 'rahul123!@#', 'title': None, 'fname': 'Shailesh', 'mname': '', 'lname': 'KUMAR', 'desg': 'Software Developer', 'creation_date': None, 'creation_time': None, 'last_visit': None, 'activation_code': None, 'auto_registered': None, 'buy_inquiry': None, 'sell_inquiry': None, 'webmail_status': '', 'account_status': '', 'section_id': None, 'heard_from': None, 'sms_balance': None, 'last_visit_time': None, 'id_verified': None, 'unmoderated_inq': None, 'tradealert_del_pref': None, 'terms_accepted': None, 'inq_orig_pref': None, 'generated_e': None, 'roaming_access': None, 'last_password_change': None, 'buy_rfis_limit': None, 'pw_hash': '', 'password_uncr': None, 'rfis_rate': None, 'avg_rfis_resp_time': None, 'show_rfis_rate': None, 'buyer_feedback': None, 'show_buyer_feedback': None, 'hide_rfis_rate': None, 'hide_buyer_feedback': None, 'inq_to_all_users': None, 'mark_inquiry_cc': None, 'user_image': None, 'miss_call_alert': None, 'merchant_account_id': None, 'google_tnc_accepted': None, 'google_ads_account_id': None, 'is_gmc_link_with_ads': None, 'adhaar_no': None, 'username_hi': None, 'desg_hi': None}
Profile obj ==  ProfileMaster object (26)
email_key ==  37
mobile_key ==  37
user_obj ==== UserAccounts object (37)
Cannot assign "37": "AccountEmails.userid" must be a "UserAccounts" instance.
There is some error in company registration Cannot assign "37": "AccountEmails.userid" must be a "UserAccounts" instance.
Email obj ====== EmailMaster object (34)
mobile_obj ====== MobileMaster object (34)
user_obj ====== {'_state': <django.db.models.base.ModelState object at 0x7f6d29060d60>, 'userid': 34, 'username': 'shaileshgola', 'password': 'rahul123!@#', 'title': None, 'fname': 'Shailesh', 'mname': '', 'lname': 'KUMAR', 'desg': 'Software Developer', 'creation_date': None, 'creation_time': None, 'last_visit': None, 'activation_code': None, 'auto_registered': None, 'buy_inquiry': None, 'sell_inquiry': None, 'webmail_status': '', 'account_status': '', 'section_id': None, 'heard_from': None, 'sms_balance': None, 'last_visit_time': None, 'id_verified': None, 'unmoderated_inq': None, 'tradealert_del_pref': None, 'terms_accepted': None, 'inq_orig_pref': None, 'generated_e': None, 'roaming_access': None, 'last_password_change': None, 'buy_rfis_limit': None, 'pw_hash': '', 'password_uncr': None, 'rfis_rate': None, 'avg_rfis_resp_time': None, 'show_rfis_rate': None, 'buyer_feedback': None, 'show_buyer_feedback': None, 'hide_rfis_rate': None, 'hide_buyer_feedback': None, 'inq_to_all_users': None, 'mark_inquiry_cc': None, 'user_image': None, 'miss_call_alert': None, 'merchant_account_id': None, 'google_tnc_accepted': None, 'google_ads_account_id': None, 'is_gmc_link_with_ads': None, 'adhaar_no': None, 'username_hi': None, 'desg_hi': None}
Profile obj ==  ProfileMaster object (23)
email_key ==  34
mobile_key ==  34
user_obj ==== UserAccounts object (34)
Cannot assign "34": "AccountEmails.userid" must be a "UserAccounts" instance.
There is some error in company registration Cannot assign "34": "AccountEmails.userid" must be a "UserAccounts" instance.
Email obj ====== EmailMaster object (30)
mobile_obj ====== MobileMaster object (30)
user_obj ====== UserAccounts object (30)
Profile obj ==  ProfileMaster object (19)
email_key ==  30
mobile_key ==  30
Cannot assign "30": "AccountEmails.userid" must be a "UserAccounts" instance.
There is some error in company registration Cannot assign "30": "AccountEmails.userid" must be a "UserAccounts" instance.
Email obj ====== EmailMaster object (31)
mobile_obj ====== MobileMaster object (31)
user_obj ====== UserAccounts object (31)
Profile obj ==  ProfileMaster object (20)
email_key ==  31
mobile_key ==  31
Cannot assign "31": "AccountEmails.userid" must be a "UserAccounts" instance.
There is some error in company registration Cannot assign "31": "AccountEmails.userid" must be a "UserAccounts" instance.
Email obj ====== EmailMaster object (32)
mobile_obj ====== MobileMaster object (32)
user_obj ====== UserAccounts object (32)
Profile obj ==  ProfileMaster object (21)
email_key ==  32
mobile_key ==  32
Cannot assign "32": "AccountEmails.userid" must be a "UserAccounts" instance.
There is some error in company registration Cannot assign "32": "AccountEmails.userid" must be a "UserAccounts" instance.
Email obj ====== EmailMaster object (33)
mobile_obj ====== MobileMaster object (33)
user_obj ====== UserAccounts object (33)
Profile obj ==  ProfileMaster object (22)
email_key ==  33
mobile_key ==  33
Cannot assign "33": "AccountEmails.userid" must be a "UserAccounts" instance.
There is some error in company registration Cannot assign "33": "AccountEmails.userid" must be a "UserAccounts" instance.
Internal Server Error: /martcrm/create_company
Traceback (most recent call last):
  File "/home/shivmarb/virtualenv/erp.mart4trade.com/3.8/lib/python3.8/site-packages/django/core/handlers/exception.py", line 47, in inner
    response = get_response(request)
  File "/home/shivmarb/virtualenv/erp.mart4trade.com/3.8/lib/python3.8/site-packages/django/core/handlers/base.py", line 179, in _get_response
    response = wrapped_callback(request, *callback_args, **callback_kwargs)
  File "/home/shivmarb/erp.mart4trade.com/martcrm/views.py", line 274, in create_company
    profile_obj = create_profile(request,**kwargs)
  File "/home/shivmarb/erp.mart4trade.com/martcrm/helper/register_profile.py", line 59, in create_profile
    acc_email_obj = AccountEmails.objects.create(userid=user_obj.userid, email_key=email_key)
  File "/home/shivmarb/virtualenv/erp.mart4trade.com/3.8/lib/python3.8/site-packages/django/db/models/manager.py", line 85, in manager_method
    return getattr(self.get_queryset(), name)(*args, **kwargs)
  File "/home/shivmarb/virtualenv/erp.mart4trade.com/3.8/lib/python3.8/site-packages/django/db/models/query.py", line 445, in create
    obj = self.model(**kwargs)
  File "/home/shivmarb/virtualenv/erp.mart4trade.com/3.8/lib/python3.8/site-packages/django/db/models/base.py", line 483, in __init__
    _setattr(self, field.name, rel_obj)
  File "/home/shivmarb/virtualenv/erp.mart4trade.com/3.8/lib/python3.8/site-packages/django/db/models/fields/related_descriptors.py", line 215, in __set__
    raise ValueError(
ValueError: Cannot assign "38": "AccountEmails.userid" must be a "UserAccounts" instance.
Internal Server Error: /martcrm/create_company
Traceback (most recent call last):
  File "/home/shivmarb/virtualenv/erp.mart4trade.com/3.8/lib/python3.8/site-packages/django/core/handlers/exception.py", line 47, in inner
    response = get_response(request)
  File "/home/shivmarb/virtualenv/erp.mart4trade.com/3.8/lib/python3.8/site-packages/django/core/handlers/base.py", line 179, in _get_response
    response = wrapped_callback(request, *callback_args, **callback_kwargs)
  File "/home/shivmarb/erp.mart4trade.com/martcrm/views.py", line 274, in create_company
    profile_obj = create_profile(request,**kwargs)
  File "/home/shivmarb/erp.mart4trade.com/martcrm/helper/register_profile.py", line 59, in create_profile
    acc_email_obj = AccountEmails.objects.create(userid=user_obj.userid, email_key=email_key)
  File "/home/shivmarb/virtualenv/erp.mart4trade.com/3.8/lib/python3.8/site-packages/django/db/models/manager.py", line 85, in manager_method
    return getattr(self.get_queryset(), name)(*args, **kwargs)
  File "/home/shivmarb/virtualenv/erp.mart4trade.com/3.8/lib/python3.8/site-packages/django/db/models/query.py", line 445, in create
    obj = self.model(**kwargs)
  File "/home/shivmarb/virtualenv/erp.mart4trade.com/3.8/lib/python3.8/site-packages/django/db/models/base.py", line 483, in __init__
    _setattr(self, field.name, rel_obj)
  File "/home/shivmarb/virtualenv/erp.mart4trade.com/3.8/lib/python3.8/site-packages/django/db/models/fields/related_descriptors.py", line 215, in __set__
    raise ValueError(
ValueError: Cannot assign "39": "AccountEmails.userid" must be a "UserAccounts" instance.
Email obj ====== EmailMaster object (38)
mobile_obj ====== MobileMaster object (38)
user_obj ====== {'_state': <django.db.models.base.ModelState object at 0x7f6d29060d60>, 'userid': 38, 'username': 'shaileshgola', 'password': 'rahul123!@#', 'title': None, 'fname': 'Shailesh', 'mname': '', 'lname': 'KUMAR', 'desg': 'Software Developer', 'creation_date': None, 'creation_time': None, 'last_visit': None, 'activation_code': None, 'auto_registered': None, 'buy_inquiry': None, 'sell_inquiry': None, 'webmail_status': '', 'account_status': '', 'section_id': None, 'heard_from': None, 'sms_balance': None, 'last_visit_time': None, 'id_verified': None, 'unmoderated_inq': None, 'tradealert_del_pref': None, 'terms_accepted': None, 'inq_orig_pref': None, 'generated_e': None, 'roaming_access': None, 'last_password_change': None, 'buy_rfis_limit': None, 'pw_hash': '', 'password_uncr': None, 'rfis_rate': None, 'avg_rfis_resp_time': None, 'show_rfis_rate': None, 'buyer_feedback': None, 'show_buyer_feedback': None, 'hide_rfis_rate': None, 'hide_buyer_feedback': None, 'inq_to_all_users': None, 'mark_inquiry_cc': None, 'user_image': None, 'miss_call_alert': None, 'merchant_account_id': None, 'google_tnc_accepted': None, 'google_ads_account_id': None, 'is_gmc_link_with_ads': None, 'adhaar_no': None, 'username_hi': None, 'desg_hi': None}
Profile obj ==  ProfileMaster object (27)
email_key ==  38
mobile_key ==  38
user_user_id ==== 38
Cannot assign "38": "AccountEmails.userid" must be a "UserAccounts" instance.
There is some error in company registration Cannot assign "38": "AccountEmails.userid" must be a "UserAccounts" instance.
Email obj ====== EmailMaster object (39)
mobile_obj ====== MobileMaster object (39)
user_obj ====== {'_state': <django.db.models.base.ModelState object at 0x7f6d290416a0>, 'userid': 39, 'username': 'shaileshgola', 'password': 'rahul123!@#', 'title': None, 'fname': 'Shailesh', 'mname': '', 'lname': 'KUMAR', 'desg': 'Software Developer', 'creation_date': None, 'creation_time': None, 'last_visit': None, 'activation_code': None, 'auto_registered': None, 'buy_inquiry': None, 'sell_inquiry': None, 'webmail_status': '', 'account_status': '', 'section_id': None, 'heard_from': None, 'sms_balance': None, 'last_visit_time': None, 'id_verified': None, 'unmoderated_inq': None, 'tradealert_del_pref': None, 'terms_accepted': None, 'inq_orig_pref': None, 'generated_e': None, 'roaming_access': None, 'last_password_change': None, 'buy_rfis_limit': None, 'pw_hash': '', 'password_uncr': None, 'rfis_rate': None, 'avg_rfis_resp_time': None, 'show_rfis_rate': None, 'buyer_feedback': None, 'show_buyer_feedback': None, 'hide_rfis_rate': None, 'hide_buyer_feedback': None, 'inq_to_all_users': None, 'mark_inquiry_cc': None, 'user_image': None, 'miss_call_alert': None, 'merchant_account_id': None, 'google_tnc_accepted': None, 'google_ads_account_id': None, 'is_gmc_link_with_ads': None, 'adhaar_no': None, 'username_hi': None, 'desg_hi': None}
Profile obj ==  ProfileMaster object (28)
email_key ==  39
mobile_key ==  39
user_user_id ==== 39
Cannot assign "39": "AccountEmails.userid" must be a "UserAccounts" instance.
There is some error in company registration Cannot assign "39": "AccountEmails.userid" must be a "UserAccounts" instance.
Internal Server Error: /martcrm/create_company
Traceback (most recent call last):
  File "/home/shivmarb/virtualenv/erp.mart4trade.com/3.8/lib/python3.8/site-packages/django/core/handlers/exception.py", line 47, in inner
    response = get_response(request)
  File "/home/shivmarb/virtualenv/erp.mart4trade.com/3.8/lib/python3.8/site-packages/django/core/handlers/base.py", line 179, in _get_response
    response = wrapped_callback(request, *callback_args, **callback_kwargs)
  File "/home/shivmarb/erp.mart4trade.com/martcrm/views.py", line 274, in create_company
    profile_obj = create_profile(request,**kwargs)
  File "/home/shivmarb/erp.mart4trade.com/martcrm/helper/register_profile.py", line 59, in create_profile
    acc_email_obj = AccountEmails.objects.create(userid=user_obj.userid, email_key=email_key)
  File "/home/shivmarb/virtualenv/erp.mart4trade.com/3.8/lib/python3.8/site-packages/django/db/models/manager.py", line 85, in manager_method
    return getattr(self.get_queryset(), name)(*args, **kwargs)
  File "/home/shivmarb/virtualenv/erp.mart4trade.com/3.8/lib/python3.8/site-packages/django/db/models/query.py", line 445, in create
    obj = self.model(**kwargs)
  File "/home/shivmarb/virtualenv/erp.mart4trade.com/3.8/lib/python3.8/site-packages/django/db/models/base.py", line 483, in __init__
    _setattr(self, field.name, rel_obj)
  File "/home/shivmarb/virtualenv/erp.mart4trade.com/3.8/lib/python3.8/site-packages/django/db/models/fields/related_descriptors.py", line 215, in __set__
    raise ValueError(
ValueError: Cannot assign "40": "AccountEmails.userid" must be a "UserAccounts" instance.
Email obj ====== EmailMaster object (40)
mobile_obj ====== MobileMaster object (40)
user_obj ====== {'_state': <django.db.models.base.ModelState object at 0x7f6d29060d90>, 'userid': 40, 'username': 'shaileshgola', 'password': 'rahul123!@#', 'title': None, 'fname': 'Shailesh', 'mname': '', 'lname': 'KUMAR', 'desg': 'Software Developer', 'creation_date': None, 'creation_time': None, 'last_visit': None, 'activation_code': None, 'auto_registered': None, 'buy_inquiry': None, 'sell_inquiry': None, 'webmail_status': '', 'account_status': '', 'section_id': None, 'heard_from': None, 'sms_balance': None, 'last_visit_time': None, 'id_verified': None, 'unmoderated_inq': None, 'tradealert_del_pref': None, 'terms_accepted': None, 'inq_orig_pref': None, 'generated_e': None, 'roaming_access': None, 'last_password_change': None, 'buy_rfis_limit': None, 'pw_hash': '', 'password_uncr': None, 'rfis_rate': None, 'avg_rfis_resp_time': None, 'show_rfis_rate': None, 'buyer_feedback': None, 'show_buyer_feedback': None, 'hide_rfis_rate': None, 'hide_buyer_feedback': None, 'inq_to_all_users': None, 'mark_inquiry_cc': None, 'user_image': None, 'miss_call_alert': None, 'merchant_account_id': None, 'google_tnc_accepted': None, 'google_ads_account_id': None, 'is_gmc_link_with_ads': None, 'adhaar_no': None, 'username_hi': None, 'desg_hi': None}
Profile obj ==  ProfileMaster object (29)
email_key ==  40
mobile_key ==  40
user_user_id ==== 40
Cannot assign "40": "AccountEmails.userid" must be a "UserAccounts" instance.
There is some error in company registration Cannot assign "40": "AccountEmails.userid" must be a "UserAccounts" instance.
Internal Server Error: /martcrm/create_company
Traceback (most recent call last):
  File "/home/shivmarb/virtualenv/erp.mart4trade.com/3.8/lib/python3.8/site-packages/django/core/handlers/exception.py", line 47, in inner
    response = get_response(request)
  File "/home/shivmarb/virtualenv/erp.mart4trade.com/3.8/lib/python3.8/site-packages/django/core/handlers/base.py", line 179, in _get_response
    response = wrapped_callback(request, *callback_args, **callback_kwargs)
  File "/home/shivmarb/erp.mart4trade.com/martcrm/views.py", line 274, in create_company
    profile_obj = create_profile(request,**kwargs)
  File "/home/shivmarb/erp.mart4trade.com/martcrm/helper/register_profile.py", line 59, in create_profile
    acc_email_obj = AccountEmails.objects.create(userid=user_obj, email_key=email_key)
  File "/home/shivmarb/virtualenv/erp.mart4trade.com/3.8/lib/python3.8/site-packages/django/db/models/manager.py", line 85, in manager_method
    return getattr(self.get_queryset(), name)(*args, **kwargs)
  File "/home/shivmarb/virtualenv/erp.mart4trade.com/3.8/lib/python3.8/site-packages/django/db/models/query.py", line 445, in create
    obj = self.model(**kwargs)
  File "/home/shivmarb/virtualenv/erp.mart4trade.com/3.8/lib/python3.8/site-packages/django/db/models/base.py", line 483, in __init__
    _setattr(self, field.name, rel_obj)
  File "/home/shivmarb/virtualenv/erp.mart4trade.com/3.8/lib/python3.8/site-packages/django/db/models/fields/related_descriptors.py", line 215, in __set__
    raise ValueError(
ValueError: Cannot assign "41": "AccountEmails.email_key" must be a "EmailMaster" instance.
Not Found: /favicon.ico
Internal Server Error: /martcrm/create_company
Traceback (most recent call last):
  File "/home/shivmarb/virtualenv/erp.mart4trade.com/3.8/lib/python3.8/site-packages/django/core/handlers/exception.py", line 47, in inner
    response = get_response(request)
  File "/home/shivmarb/virtualenv/erp.mart4trade.com/3.8/lib/python3.8/site-packages/django/core/handlers/base.py", line 179, in _get_response
    response = wrapped_callback(request, *callback_args, **callback_kwargs)
  File "/home/shivmarb/erp.mart4trade.com/martcrm/views.py", line 274, in create_company
    profile_obj = create_profile(request,**kwargs)
  File "/home/shivmarb/erp.mart4trade.com/martcrm/helper/register_profile.py", line 59, in create_profile
    acc_email_obj = AccountEmails.objects.create(userid=user_obj, email_key=email_obj)
  File "/home/shivmarb/virtualenv/erp.mart4trade.com/3.8/lib/python3.8/site-packages/django/db/models/manager.py", line 85, in manager_method
    return getattr(self.get_queryset(), name)(*args, **kwargs)
  File "/home/shivmarb/virtualenv/erp.mart4trade.com/3.8/lib/python3.8/site-packages/django/db/models/query.py", line 445, in create
    obj = self.model(**kwargs)
  File "/home/shivmarb/virtualenv/erp.mart4trade.com/3.8/lib/python3.8/site-packages/django/db/models/base.py", line 483, in __init__
    _setattr(self, field.name, rel_obj)
  File "/home/shivmarb/virtualenv/erp.mart4trade.com/3.8/lib/python3.8/site-packages/django/db/models/fields/related_descriptors.py", line 215, in __set__
    raise ValueError(
ValueError: Cannot assign "42": "AccountEmails.email_key" must be a "EmailMaster" instance.
Not Found: /favicon.ico
Not Found: /martcrm/assets/img/favicon.png
Internal Server Error: /martcrm/create_company
Traceback (most recent call last):
  File "/home/shivmarb/virtualenv/erp.mart4trade.com/3.8/lib/python3.8/site-packages/django/db/backends/utils.py", line 84, in _execute
    return self.cursor.execute(sql, params)
psycopg2.errors.NotNullViolation: null value in column "ifdefault" violates not-null constraint
DETAIL:  Failing row contains (43, 43, null, 1).


The above exception was the direct cause of the following exception:

Traceback (most recent call last):
  File "/home/shivmarb/virtualenv/erp.mart4trade.com/3.8/lib/python3.8/site-packages/django/core/handlers/exception.py", line 47, in inner
    response = get_response(request)
  File "/home/shivmarb/virtualenv/erp.mart4trade.com/3.8/lib/python3.8/site-packages/django/core/handlers/base.py", line 179, in _get_response
    response = wrapped_callback(request, *callback_args, **callback_kwargs)
  File "/home/shivmarb/erp.mart4trade.com/martcrm/views.py", line 274, in create_company
    profile_obj = create_profile(request,**kwargs)
  File "/home/shivmarb/erp.mart4trade.com/martcrm/helper/register_profile.py", line 59, in create_profile
    acc_email_obj = AccountEmails.objects.create(userid=user_obj, email_key=email_obj)
  File "/home/shivmarb/virtualenv/erp.mart4trade.com/3.8/lib/python3.8/site-packages/django/db/models/manager.py", line 85, in manager_method
    return getattr(self.get_queryset(), name)(*args, **kwargs)
  File "/home/shivmarb/virtualenv/erp.mart4trade.com/3.8/lib/python3.8/site-packages/django/db/models/query.py", line 447, in create
    obj.save(force_insert=True, using=self.db)
  File "/home/shivmarb/virtualenv/erp.mart4trade.com/3.8/lib/python3.8/site-packages/django/db/models/base.py", line 750, in save
    self.save_base(using=using, force_insert=force_insert,
  File "/home/shivmarb/virtualenv/erp.mart4trade.com/3.8/lib/python3.8/site-packages/django/db/models/base.py", line 787, in save_base
    updated = self._save_table(
  File "/home/shivmarb/virtualenv/erp.mart4trade.com/3.8/lib/python3.8/site-packages/django/db/models/base.py", line 892, in _save_table
    results = self._do_insert(cls._base_manager, using, fields, returning_fields, raw)
  File "/home/shivmarb/virtualenv/erp.mart4trade.com/3.8/lib/python3.8/site-packages/django/db/models/base.py", line 930, in _do_insert
    return manager._insert(
  File "/home/shivmarb/virtualenv/erp.mart4trade.com/3.8/lib/python3.8/site-packages/django/db/models/manager.py", line 85, in manager_method
    return getattr(self.get_queryset(), name)(*args, **kwargs)
  File "/home/shivmarb/virtualenv/erp.mart4trade.com/3.8/lib/python3.8/site-packages/django/db/models/query.py", line 1249, in _insert
    return query.get_compiler(using=using).execute_sql(returning_fields)
  File "/home/shivmarb/virtualenv/erp.mart4trade.com/3.8/lib/python3.8/site-packages/django/db/models/sql/compiler.py", line 1395, in execute_sql
    cursor.execute(sql, params)
  File "/home/shivmarb/virtualenv/erp.mart4trade.com/3.8/lib/python3.8/site-packages/django/db/backends/utils.py", line 98, in execute
    return super().execute(sql, params)
  File "/home/shivmarb/virtualenv/erp.mart4trade.com/3.8/lib/python3.8/site-packages/django/db/backends/utils.py", line 66, in execute
    return self._execute_with_wrappers(sql, params, many=False, executor=self._execute)
  File "/home/shivmarb/virtualenv/erp.mart4trade.com/3.8/lib/python3.8/site-packages/django/db/backends/utils.py", line 75, in _execute_with_wrappers
    return executor(sql, params, many, context)
  File "/home/shivmarb/virtualenv/erp.mart4trade.com/3.8/lib/python3.8/site-packages/django/db/backends/utils.py", line 84, in _execute
    return self.cursor.execute(sql, params)
  File "/home/shivmarb/virtualenv/erp.mart4trade.com/3.8/lib/python3.8/site-packages/django/db/utils.py", line 90, in __exit__
    raise dj_exc_value.with_traceback(traceback) from exc_value
  File "/home/shivmarb/virtualenv/erp.mart4trade.com/3.8/lib/python3.8/site-packages/django/db/backends/utils.py", line 84, in _execute
    return self.cursor.execute(sql, params)
django.db.utils.IntegrityError: null value in column "ifdefault" violates not-null constraint
DETAIL:  Failing row contains (43, 43, null, 1).

Internal Server Error: /martcrm/create_company
Traceback (most recent call last):
  File "/home/shivmarb/virtualenv/erp.mart4trade.com/3.8/lib/python3.8/site-packages/django/core/handlers/exception.py", line 47, in inner
    response = get_response(request)
  File "/home/shivmarb/virtualenv/erp.mart4trade.com/3.8/lib/python3.8/site-packages/django/core/handlers/base.py", line 179, in _get_response
    response = wrapped_callback(request, *callback_args, **callback_kwargs)
  File "/home/shivmarb/erp.mart4trade.com/martcrm/views.py", line 274, in create_company
    profile_obj = create_profile(request,**kwargs)
  File "/home/shivmarb/erp.mart4trade.com/martcrm/helper/register_profile.py", line 59, in create_profile
    acc_email_obj = AccountEmails.objects.create(userid=user_obj, email_key=email_obj)
  File "/home/shivmarb/virtualenv/erp.mart4trade.com/3.8/lib/python3.8/site-packages/django/db/models/manager.py", line 85, in manager_method
    return getattr(self.get_queryset(), name)(*args, **kwargs)
  File "/home/shivmarb/virtualenv/erp.mart4trade.com/3.8/lib/python3.8/site-packages/django/db/models/query.py", line 445, in create
    obj = self.model(**kwargs)
  File "/home/shivmarb/virtualenv/erp.mart4trade.com/3.8/lib/python3.8/site-packages/django/db/models/base.py", line 483, in __init__
    _setattr(self, field.name, rel_obj)
  File "/home/shivmarb/virtualenv/erp.mart4trade.com/3.8/lib/python3.8/site-packages/django/db/models/fields/related_descriptors.py", line 215, in __set__
    raise ValueError(
ValueError: Cannot assign "44": "AccountEmails.email_key" must be a "EmailMaster" instance.
Email obj ====== EmailMaster object (43)
mobile_obj ====== MobileMaster object (43)
user_obj ====== {'_state': <django.db.models.base.ModelState object at 0x7f6d2903ab50>, 'userid': 43, 'username': 'shaileshgola', 'password': 'rahul123!@#', 'title': None, 'fname': 'Shailesh', 'mname': '', 'lname': 'KUMAR', 'desg': 'Software Developer', 'creation_date': None, 'creation_time': None, 'last_visit': None, 'activation_code': None, 'auto_registered': None, 'buy_inquiry': None, 'sell_inquiry': None, 'webmail_status': '', 'account_status': '', 'section_id': None, 'heard_from': None, 'sms_balance': None, 'last_visit_time': None, 'id_verified': None, 'unmoderated_inq': None, 'tradealert_del_pref': None, 'terms_accepted': None, 'inq_orig_pref': None, 'generated_e': None, 'roaming_access': None, 'last_password_change': None, 'buy_rfis_limit': None, 'pw_hash': '', 'password_uncr': None, 'rfis_rate': None, 'avg_rfis_resp_time': None, 'show_rfis_rate': None, 'buyer_feedback': None, 'show_buyer_feedback': None, 'hide_rfis_rate': None, 'hide_buyer_feedback': None, 'inq_to_all_users': None, 'mark_inquiry_cc': None, 'user_image': None, 'miss_call_alert': None, 'merchant_account_id': None, 'google_tnc_accepted': None, 'google_ads_account_id': None, 'is_gmc_link_with_ads': None, 'adhaar_no': None, 'username_hi': None, 'desg_hi': None}
Profile obj ==  ProfileMaster object (32)
email_key ==  43
mobile_key ==  43
user_user_id ==== 43
null value in column "ifdefault" violates not-null constraint
DETAIL:  Failing row contains (43, 43, null, 1).

There is some error in company registration null value in column "ifdefault" violates not-null constraint
DETAIL:  Failing row contains (43, 43, null, 1).

Internal Server Error: /martcrm/create_company
Traceback (most recent call last):
  File "/home/shivmarb/virtualenv/erp.mart4trade.com/3.8/lib/python3.8/site-packages/django/core/handlers/exception.py", line 47, in inner
    response = get_response(request)
  File "/home/shivmarb/virtualenv/erp.mart4trade.com/3.8/lib/python3.8/site-packages/django/core/handlers/base.py", line 179, in _get_response
    response = wrapped_callback(request, *callback_args, **callback_kwargs)
  File "/home/shivmarb/erp.mart4trade.com/martcrm/views.py", line 274, in create_company
    profile_obj = create_profile(request,**kwargs)
  File "/home/shivmarb/erp.mart4trade.com/martcrm/helper/register_profile.py", line 59, in create_profile
    acc_email_obj = AccountEmails.objects.create(userid=user_obj, email_key=email_obj)
  File "/home/shivmarb/virtualenv/erp.mart4trade.com/3.8/lib/python3.8/site-packages/django/db/models/manager.py", line 85, in manager_method
    return getattr(self.get_queryset(), name)(*args, **kwargs)
  File "/home/shivmarb/virtualenv/erp.mart4trade.com/3.8/lib/python3.8/site-packages/django/db/models/query.py", line 445, in create
    obj = self.model(**kwargs)
  File "/home/shivmarb/virtualenv/erp.mart4trade.com/3.8/lib/python3.8/site-packages/django/db/models/base.py", line 483, in __init__
    _setattr(self, field.name, rel_obj)
  File "/home/shivmarb/virtualenv/erp.mart4trade.com/3.8/lib/python3.8/site-packages/django/db/models/fields/related_descriptors.py", line 215, in __set__
    raise ValueError(
ValueError: Cannot assign "45": "AccountEmails.email_key" must be a "EmailMaster" instance.
Internal Server Error: /martcrm/create_company
Traceback (most recent call last):
  File "/home/shivmarb/virtualenv/erp.mart4trade.com/3.8/lib/python3.8/site-packages/django/core/handlers/exception.py", line 47, in inner
    response = get_response(request)
  File "/home/shivmarb/virtualenv/erp.mart4trade.com/3.8/lib/python3.8/site-packages/django/core/handlers/base.py", line 179, in _get_response
    response = wrapped_callback(request, *callback_args, **callback_kwargs)
  File "/home/shivmarb/erp.mart4trade.com/martcrm/views.py", line 274, in create_company
    profile_obj = create_profile(request,**kwargs)
  File "/home/shivmarb/erp.mart4trade.com/martcrm/helper/register_profile.py", line 59, in create_profile
    acc_email_obj = AccountEmails.objects.create(userid=user_obj, email_key=email_obj)
  File "/home/shivmarb/virtualenv/erp.mart4trade.com/3.8/lib/python3.8/site-packages/django/db/models/manager.py", line 85, in manager_method
    return getattr(self.get_queryset(), name)(*args, **kwargs)
  File "/home/shivmarb/virtualenv/erp.mart4trade.com/3.8/lib/python3.8/site-packages/django/db/models/query.py", line 445, in create
    obj = self.model(**kwargs)
  File "/home/shivmarb/virtualenv/erp.mart4trade.com/3.8/lib/python3.8/site-packages/django/db/models/base.py", line 483, in __init__
    _setattr(self, field.name, rel_obj)
  File "/home/shivmarb/virtualenv/erp.mart4trade.com/3.8/lib/python3.8/site-packages/django/db/models/fields/related_descriptors.py", line 215, in __set__
    raise ValueError(
ValueError: Cannot assign "46": "AccountEmails.email_key" must be a "EmailMaster" instance.
Email obj ====== EmailMaster object (41)
mobile_obj ====== MobileMaster object (41)
user_obj ====== {'_state': <django.db.models.base.ModelState object at 0x7f6d29060d60>, 'userid': 41, 'username': 'shaileshgola', 'password': 'rahul123!@#', 'title': None, 'fname': 'Shailesh', 'mname': '', 'lname': 'KUMAR', 'desg': 'Software Developer', 'creation_date': None, 'creation_time': None, 'last_visit': None, 'activation_code': None, 'auto_registered': None, 'buy_inquiry': None, 'sell_inquiry': None, 'webmail_status': '', 'account_status': '', 'section_id': None, 'heard_from': None, 'sms_balance': None, 'last_visit_time': None, 'id_verified': None, 'unmoderated_inq': None, 'tradealert_del_pref': None, 'terms_accepted': None, 'inq_orig_pref': None, 'generated_e': None, 'roaming_access': None, 'last_password_change': None, 'buy_rfis_limit': None, 'pw_hash': '', 'password_uncr': None, 'rfis_rate': None, 'avg_rfis_resp_time': None, 'show_rfis_rate': None, 'buyer_feedback': None, 'show_buyer_feedback': None, 'hide_rfis_rate': None, 'hide_buyer_feedback': None, 'inq_to_all_users': None, 'mark_inquiry_cc': None, 'user_image': None, 'miss_call_alert': None, 'merchant_account_id': None, 'google_tnc_accepted': None, 'google_ads_account_id': None, 'is_gmc_link_with_ads': None, 'adhaar_no': None, 'username_hi': None, 'desg_hi': None}
Profile obj ==  ProfileMaster object (30)
email_key ==  41
mobile_key ==  41
user_user_id ==== 41
Cannot assign "41": "AccountEmails.email_key" must be a "EmailMaster" instance.
There is some error in company registration Cannot assign "41": "AccountEmails.email_key" must be a "EmailMaster" instance.
Email obj ====== EmailMaster object (42)
mobile_obj ====== MobileMaster object (42)
user_obj ====== {'_state': <django.db.models.base.ModelState object at 0x7f6d2904cdc0>, 'userid': 42, 'username': 'shaileshgola', 'password': 'rahul123!@#', 'title': None, 'fname': 'Shailesh', 'mname': '', 'lname': 'KUMAR', 'desg': 'Software Developer', 'creation_date': None, 'creation_time': None, 'last_visit': None, 'activation_code': None, 'auto_registered': None, 'buy_inquiry': None, 'sell_inquiry': None, 'webmail_status': '', 'account_status': '', 'section_id': None, 'heard_from': None, 'sms_balance': None, 'last_visit_time': None, 'id_verified': None, 'unmoderated_inq': None, 'tradealert_del_pref': None, 'terms_accepted': None, 'inq_orig_pref': None, 'generated_e': None, 'roaming_access': None, 'last_password_change': None, 'buy_rfis_limit': None, 'pw_hash': '', 'password_uncr': None, 'rfis_rate': None, 'avg_rfis_resp_time': None, 'show_rfis_rate': None, 'buyer_feedback': None, 'show_buyer_feedback': None, 'hide_rfis_rate': None, 'hide_buyer_feedback': None, 'inq_to_all_users': None, 'mark_inquiry_cc': None, 'user_image': None, 'miss_call_alert': None, 'merchant_account_id': None, 'google_tnc_accepted': None, 'google_ads_account_id': None, 'is_gmc_link_with_ads': None, 'adhaar_no': None, 'username_hi': None, 'desg_hi': None}
Profile obj ==  ProfileMaster object (31)
email_key ==  42
mobile_key ==  42
user_user_id ==== 42
Cannot assign "42": "AccountEmails.email_key" must be a "EmailMaster" instance.
There is some error in company registration Cannot assign "42": "AccountEmails.email_key" must be a "EmailMaster" instance.
Email obj ====== EmailMaster object (44)
mobile_obj ====== MobileMaster object (44)
user_obj ====== {'_state': <django.db.models.base.ModelState object at 0x7f6d29045160>, 'userid': 44, 'username': 'shaileshgola', 'password': 'rahul123!@#', 'title': None, 'fname': 'Shailesh', 'mname': '', 'lname': 'KUMAR', 'desg': 'Software Developer', 'creation_date': None, 'creation_time': None, 'last_visit': None, 'activation_code': None, 'auto_registered': None, 'buy_inquiry': None, 'sell_inquiry': None, 'webmail_status': '', 'account_status': '', 'section_id': None, 'heard_from': None, 'sms_balance': None, 'last_visit_time': None, 'id_verified': None, 'unmoderated_inq': None, 'tradealert_del_pref': None, 'terms_accepted': None, 'inq_orig_pref': None, 'generated_e': None, 'roaming_access': None, 'last_password_change': None, 'buy_rfis_limit': None, 'pw_hash': '', 'password_uncr': None, 'rfis_rate': None, 'avg_rfis_resp_time': None, 'show_rfis_rate': None, 'buyer_feedback': None, 'show_buyer_feedback': None, 'hide_rfis_rate': None, 'hide_buyer_feedback': None, 'inq_to_all_users': None, 'mark_inquiry_cc': None, 'user_image': None, 'miss_call_alert': None, 'merchant_account_id': None, 'google_tnc_accepted': None, 'google_ads_account_id': None, 'is_gmc_link_with_ads': None, 'adhaar_no': None, 'username_hi': None, 'desg_hi': None}
Profile obj ==  ProfileMaster object (33)
email_key ==  44
mobile_key ==  44
user_user_id ==== 44
Cannot assign "44": "AccountEmails.email_key" must be a "EmailMaster" instance.
There is some error in company registration Cannot assign "44": "AccountEmails.email_key" must be a "EmailMaster" instance.
Email obj ====== EmailMaster object (45)
mobile_obj ====== MobileMaster object (45)
user_obj ====== {'_state': <django.db.models.base.ModelState object at 0x7f6d29085eb0>, 'userid': 45, 'username': 'shaileshgola', 'password': 'rahul123!@#', 'title': None, 'fname': 'Shailesh', 'mname': '', 'lname': 'KUMAR', 'desg': 'Software Developer', 'creation_date': None, 'creation_time': None, 'last_visit': None, 'activation_code': None, 'auto_registered': None, 'buy_inquiry': None, 'sell_inquiry': None, 'webmail_status': '', 'account_status': '', 'section_id': None, 'heard_from': None, 'sms_balance': None, 'last_visit_time': None, 'id_verified': None, 'unmoderated_inq': None, 'tradealert_del_pref': None, 'terms_accepted': None, 'inq_orig_pref': None, 'generated_e': None, 'roaming_access': None, 'last_password_change': None, 'buy_rfis_limit': None, 'pw_hash': '', 'password_uncr': None, 'rfis_rate': None, 'avg_rfis_resp_time': None, 'show_rfis_rate': None, 'buyer_feedback': None, 'show_buyer_feedback': None, 'hide_rfis_rate': None, 'hide_buyer_feedback': None, 'inq_to_all_users': None, 'mark_inquiry_cc': None, 'user_image': None, 'miss_call_alert': None, 'merchant_account_id': None, 'google_tnc_accepted': None, 'google_ads_account_id': None, 'is_gmc_link_with_ads': None, 'adhaar_no': None, 'username_hi': None, 'desg_hi': None}
Profile obj ==  ProfileMaster object (34)
email_key ==  45
mobile_key ==  45
user_user_id ==== 45
Cannot assign "45": "AccountEmails.email_key" must be a "EmailMaster" instance.
There is some error in company registration Cannot assign "45": "AccountEmails.email_key" must be a "EmailMaster" instance.
Email obj ====== EmailMaster object (46)
mobile_obj ====== MobileMaster object (46)
user_obj ====== {'_state': <django.db.models.base.ModelState object at 0x7f6d28fd1fd0>, 'userid': 46, 'username': 'shaileshgola', 'password': 'rahul123!@#', 'title': None, 'fname': 'Shailesh', 'mname': '', 'lname': 'KUMAR', 'desg': 'Software Developer', 'creation_date': None, 'creation_time': None, 'last_visit': None, 'activation_code': None, 'auto_registered': None, 'buy_inquiry': None, 'sell_inquiry': None, 'webmail_status': '', 'account_status': '', 'section_id': None, 'heard_from': None, 'sms_balance': None, 'last_visit_time': None, 'id_verified': None, 'unmoderated_inq': None, 'tradealert_del_pref': None, 'terms_accepted': None, 'inq_orig_pref': None, 'generated_e': None, 'roaming_access': None, 'last_password_change': None, 'buy_rfis_limit': None, 'pw_hash': '', 'password_uncr': None, 'rfis_rate': None, 'avg_rfis_resp_time': None, 'show_rfis_rate': None, 'buyer_feedback': None, 'show_buyer_feedback': None, 'hide_rfis_rate': None, 'hide_buyer_feedback': None, 'inq_to_all_users': None, 'mark_inquiry_cc': None, 'user_image': None, 'miss_call_alert': None, 'merchant_account_id': None, 'google_tnc_accepted': None, 'google_ads_account_id': None, 'is_gmc_link_with_ads': None, 'adhaar_no': None, 'username_hi': None, 'desg_hi': None}
Profile obj ==  ProfileMaster object (35)
email_key ==  46
mobile_key ==  46
user_user_id ==== 46
Cannot assign "46": "AccountEmails.email_key" must be a "EmailMaster" instance.
There is some error in company registration Cannot assign "46": "AccountEmails.email_key" must be a "EmailMaster" instance.
Internal Server Error: /martcrm/create_company
Traceback (most recent call last):
  File "/home/shivmarb/virtualenv/erp.mart4trade.com/3.8/lib/python3.8/site-packages/django/db/backends/utils.py", line 84, in _execute
    return self.cursor.execute(sql, params)
psycopg2.errors.NotNullViolation: null value in column "ifdefault" violates not-null constraint
DETAIL:  Failing row contains (47, 47, null, 2).


The above exception was the direct cause of the following exception:

Traceback (most recent call last):
  File "/home/shivmarb/virtualenv/erp.mart4trade.com/3.8/lib/python3.8/site-packages/django/core/handlers/exception.py", line 47, in inner
    response = get_response(request)
  File "/home/shivmarb/virtualenv/erp.mart4trade.com/3.8/lib/python3.8/site-packages/django/core/handlers/base.py", line 179, in _get_response
    response = wrapped_callback(request, *callback_args, **callback_kwargs)
  File "/home/shivmarb/erp.mart4trade.com/martcrm/views.py", line 274, in create_company
    profile_obj = create_profile(request,**kwargs)
  File "/home/shivmarb/erp.mart4trade.com/martcrm/helper/register_profile.py", line 59, in create_profile
    acc_email_obj = AccountEmails.objects.create(userid=user_obj, email_key=email_obj)
  File "/home/shivmarb/virtualenv/erp.mart4trade.com/3.8/lib/python3.8/site-packages/django/db/models/manager.py", line 85, in manager_method
    return getattr(self.get_queryset(), name)(*args, **kwargs)
  File "/home/shivmarb/virtualenv/erp.mart4trade.com/3.8/lib/python3.8/site-packages/django/db/models/query.py", line 447, in create
    obj.save(force_insert=True, using=self.db)
  File "/home/shivmarb/virtualenv/erp.mart4trade.com/3.8/lib/python3.8/site-packages/django/db/models/base.py", line 750, in save
    self.save_base(using=using, force_insert=force_insert,
  File "/home/shivmarb/virtualenv/erp.mart4trade.com/3.8/lib/python3.8/site-packages/django/db/models/base.py", line 787, in save_base
    updated = self._save_table(
  File "/home/shivmarb/virtualenv/erp.mart4trade.com/3.8/lib/python3.8/site-packages/django/db/models/base.py", line 892, in _save_table
    results = self._do_insert(cls._base_manager, using, fields, returning_fields, raw)
  File "/home/shivmarb/virtualenv/erp.mart4trade.com/3.8/lib/python3.8/site-packages/django/db/models/base.py", line 930, in _do_insert
    return manager._insert(
  File "/home/shivmarb/virtualenv/erp.mart4trade.com/3.8/lib/python3.8/site-packages/django/db/models/manager.py", line 85, in manager_method
    return getattr(self.get_queryset(), name)(*args, **kwargs)
  File "/home/shivmarb/virtualenv/erp.mart4trade.com/3.8/lib/python3.8/site-packages/django/db/models/query.py", line 1249, in _insert
    return query.get_compiler(using=using).execute_sql(returning_fields)
  File "/home/shivmarb/virtualenv/erp.mart4trade.com/3.8/lib/python3.8/site-packages/django/db/models/sql/compiler.py", line 1395, in execute_sql
    cursor.execute(sql, params)
  File "/home/shivmarb/virtualenv/erp.mart4trade.com/3.8/lib/python3.8/site-packages/django/db/backends/utils.py", line 98, in execute
    return super().execute(sql, params)
  File "/home/shivmarb/virtualenv/erp.mart4trade.com/3.8/lib/python3.8/site-packages/django/db/backends/utils.py", line 66, in execute
    return self._execute_with_wrappers(sql, params, many=False, executor=self._execute)
  File "/home/shivmarb/virtualenv/erp.mart4trade.com/3.8/lib/python3.8/site-packages/django/db/backends/utils.py", line 75, in _execute_with_wrappers
    return executor(sql, params, many, context)
  File "/home/shivmarb/virtualenv/erp.mart4trade.com/3.8/lib/python3.8/site-packages/django/db/backends/utils.py", line 84, in _execute
    return self.cursor.execute(sql, params)
  File "/home/shivmarb/virtualenv/erp.mart4trade.com/3.8/lib/python3.8/site-packages/django/db/utils.py", line 90, in __exit__
    raise dj_exc_value.with_traceback(traceback) from exc_value
  File "/home/shivmarb/virtualenv/erp.mart4trade.com/3.8/lib/python3.8/site-packages/django/db/backends/utils.py", line 84, in _execute
    return self.cursor.execute(sql, params)
django.db.utils.IntegrityError: null value in column "ifdefault" violates not-null constraint
DETAIL:  Failing row contains (47, 47, null, 2).

Internal Server Error: /martcrm/create_company
Traceback (most recent call last):
  File "/home/shivmarb/virtualenv/erp.mart4trade.com/3.8/lib/python3.8/site-packages/django/db/backends/utils.py", line 84, in _execute
    return self.cursor.execute(sql, params)
psycopg2.errors.NotNullViolation: null value in column "ifdefault" violates not-null constraint
DETAIL:  Failing row contains (48, 48, null, 3).


The above exception was the direct cause of the following exception:

Traceback (most recent call last):
  File "/home/shivmarb/virtualenv/erp.mart4trade.com/3.8/lib/python3.8/site-packages/django/core/handlers/exception.py", line 47, in inner
    response = get_response(request)
  File "/home/shivmarb/virtualenv/erp.mart4trade.com/3.8/lib/python3.8/site-packages/django/core/handlers/base.py", line 179, in _get_response
    response = wrapped_callback(request, *callback_args, **callback_kwargs)
  File "/home/shivmarb/erp.mart4trade.com/martcrm/views.py", line 274, in create_company
    profile_obj = create_profile(request,**kwargs)
  File "/home/shivmarb/erp.mart4trade.com/martcrm/helper/register_profile.py", line 59, in create_profile
    acc_email_obj = AccountEmails.objects.create(userid=user_obj, email_key=email_obj,ifdefault=True)
  File "/home/shivmarb/virtualenv/erp.mart4trade.com/3.8/lib/python3.8/site-packages/django/db/models/manager.py", line 85, in manager_method
    return getattr(self.get_queryset(), name)(*args, **kwargs)
  File "/home/shivmarb/virtualenv/erp.mart4trade.com/3.8/lib/python3.8/site-packages/django/db/models/query.py", line 447, in create
    obj.save(force_insert=True, using=self.db)
  File "/home/shivmarb/virtualenv/erp.mart4trade.com/3.8/lib/python3.8/site-packages/django/db/models/base.py", line 750, in save
    self.save_base(using=using, force_insert=force_insert,
  File "/home/shivmarb/virtualenv/erp.mart4trade.com/3.8/lib/python3.8/site-packages/django/db/models/base.py", line 787, in save_base
    updated = self._save_table(
  File "/home/shivmarb/virtualenv/erp.mart4trade.com/3.8/lib/python3.8/site-packages/django/db/models/base.py", line 892, in _save_table
    results = self._do_insert(cls._base_manager, using, fields, returning_fields, raw)
  File "/home/shivmarb/virtualenv/erp.mart4trade.com/3.8/lib/python3.8/site-packages/django/db/models/base.py", line 930, in _do_insert
    return manager._insert(
  File "/home/shivmarb/virtualenv/erp.mart4trade.com/3.8/lib/python3.8/site-packages/django/db/models/manager.py", line 85, in manager_method
    return getattr(self.get_queryset(), name)(*args, **kwargs)
  File "/home/shivmarb/virtualenv/erp.mart4trade.com/3.8/lib/python3.8/site-packages/django/db/models/query.py", line 1249, in _insert
    return query.get_compiler(using=using).execute_sql(returning_fields)
  File "/home/shivmarb/virtualenv/erp.mart4trade.com/3.8/lib/python3.8/site-packages/django/db/models/sql/compiler.py", line 1395, in execute_sql
    cursor.execute(sql, params)
  File "/home/shivmarb/virtualenv/erp.mart4trade.com/3.8/lib/python3.8/site-packages/django/db/backends/utils.py", line 98, in execute
    return super().execute(sql, params)
  File "/home/shivmarb/virtualenv/erp.mart4trade.com/3.8/lib/python3.8/site-packages/django/db/backends/utils.py", line 66, in execute
    return self._execute_with_wrappers(sql, params, many=False, executor=self._execute)
  File "/home/shivmarb/virtualenv/erp.mart4trade.com/3.8/lib/python3.8/site-packages/django/db/backends/utils.py", line 75, in _execute_with_wrappers
    return executor(sql, params, many, context)
  File "/home/shivmarb/virtualenv/erp.mart4trade.com/3.8/lib/python3.8/site-packages/django/db/backends/utils.py", line 84, in _execute
    return self.cursor.execute(sql, params)
  File "/home/shivmarb/virtualenv/erp.mart4trade.com/3.8/lib/python3.8/site-packages/django/db/utils.py", line 90, in __exit__
    raise dj_exc_value.with_traceback(traceback) from exc_value
  File "/home/shivmarb/virtualenv/erp.mart4trade.com/3.8/lib/python3.8/site-packages/django/db/backends/utils.py", line 84, in _execute
    return self.cursor.execute(sql, params)
django.db.utils.IntegrityError: null value in column "ifdefault" violates not-null constraint
DETAIL:  Failing row contains (48, 48, null, 3).

Not Found: /favicon.ico
Internal Server Error: /martcrm/create_company
Traceback (most recent call last):
  File "/home/shivmarb/virtualenv/erp.mart4trade.com/3.8/lib/python3.8/site-packages/django/db/backends/utils.py", line 84, in _execute
    return self.cursor.execute(sql, params)
psycopg2.errors.NotNullViolation: null value in column "ifdefault" violates not-null constraint
DETAIL:  Failing row contains (49, 49, null, 4).


The above exception was the direct cause of the following exception:

Traceback (most recent call last):
  File "/home/shivmarb/virtualenv/erp.mart4trade.com/3.8/lib/python3.8/site-packages/django/core/handlers/exception.py", line 47, in inner
    response = get_response(request)
  File "/home/shivmarb/virtualenv/erp.mart4trade.com/3.8/lib/python3.8/site-packages/django/core/handlers/base.py", line 179, in _get_response
    response = wrapped_callback(request, *callback_args, **callback_kwargs)
  File "/home/shivmarb/erp.mart4trade.com/martcrm/views.py", line 274, in create_company
    profile_obj = create_profile(request,**kwargs)
  File "/home/shivmarb/erp.mart4trade.com/martcrm/helper/register_profile.py", line 59, in create_profile
    acc_email_obj = AccountEmails.objects.create(userid=user_obj, email_key=email_obj,ifdefault=True)
  File "/home/shivmarb/virtualenv/erp.mart4trade.com/3.8/lib/python3.8/site-packages/django/db/models/manager.py", line 85, in manager_method
    return getattr(self.get_queryset(), name)(*args, **kwargs)
  File "/home/shivmarb/virtualenv/erp.mart4trade.com/3.8/lib/python3.8/site-packages/django/db/models/query.py", line 447, in create
    obj.save(force_insert=True, using=self.db)
  File "/home/shivmarb/virtualenv/erp.mart4trade.com/3.8/lib/python3.8/site-packages/django/db/models/base.py", line 750, in save
    self.save_base(using=using, force_insert=force_insert,
  File "/home/shivmarb/virtualenv/erp.mart4trade.com/3.8/lib/python3.8/site-packages/django/db/models/base.py", line 787, in save_base
    updated = self._save_table(
  File "/home/shivmarb/virtualenv/erp.mart4trade.com/3.8/lib/python3.8/site-packages/django/db/models/base.py", line 892, in _save_table
    results = self._do_insert(cls._base_manager, using, fields, returning_fields, raw)
  File "/home/shivmarb/virtualenv/erp.mart4trade.com/3.8/lib/python3.8/site-packages/django/db/models/base.py", line 930, in _do_insert
    return manager._insert(
  File "/home/shivmarb/virtualenv/erp.mart4trade.com/3.8/lib/python3.8/site-packages/django/db/models/manager.py", line 85, in manager_method
    return getattr(self.get_queryset(), name)(*args, **kwargs)
  File "/home/shivmarb/virtualenv/erp.mart4trade.com/3.8/lib/python3.8/site-packages/django/db/models/query.py", line 1249, in _insert
    return query.get_compiler(using=using).execute_sql(returning_fields)
  File "/home/shivmarb/virtualenv/erp.mart4trade.com/3.8/lib/python3.8/site-packages/django/db/models/sql/compiler.py", line 1395, in execute_sql
    cursor.execute(sql, params)
  File "/home/shivmarb/virtualenv/erp.mart4trade.com/3.8/lib/python3.8/site-packages/django/db/backends/utils.py", line 98, in execute
    return super().execute(sql, params)
  File "/home/shivmarb/virtualenv/erp.mart4trade.com/3.8/lib/python3.8/site-packages/django/db/backends/utils.py", line 66, in execute
    return self._execute_with_wrappers(sql, params, many=False, executor=self._execute)
  File "/home/shivmarb/virtualenv/erp.mart4trade.com/3.8/lib/python3.8/site-packages/django/db/backends/utils.py", line 75, in _execute_with_wrappers
    return executor(sql, params, many, context)
  File "/home/shivmarb/virtualenv/erp.mart4trade.com/3.8/lib/python3.8/site-packages/django/db/backends/utils.py", line 84, in _execute
    return self.cursor.execute(sql, params)
  File "/home/shivmarb/virtualenv/erp.mart4trade.com/3.8/lib/python3.8/site-packages/django/db/utils.py", line 90, in __exit__
    raise dj_exc_value.with_traceback(traceback) from exc_value
  File "/home/shivmarb/virtualenv/erp.mart4trade.com/3.8/lib/python3.8/site-packages/django/db/backends/utils.py", line 84, in _execute
    return self.cursor.execute(sql, params)
django.db.utils.IntegrityError: null value in column "ifdefault" violates not-null constraint
DETAIL:  Failing row contains (49, 49, null, 4).

Not Found: /favicon.ico
Not Found: /martcrm/assets/img/favicon.png
Not Found: /martcrm/assets/img/logo.png
Not Found: /martcrm/assets/img/messages-1.jpg
Not Found: /martcrm/assets/img/messages-2.jpg
Not Found: /martcrm/assets/img/profile-img.jpg
Not Found: /martcrm/assets/img/messages-3.jpg
Not Found: /martcrm/assets/img/logo.png
Not Found: /martcrm/assets/img/messages-1.jpg
Not Found: /martcrm/assets/img/messages-2.jpg
Not Found: /martcrm/assets/img/profile-img.jpg
Not Found: /martcrm/assets/img/messages-3.jpg
Not Found: /martcrm/assets/img/logo.png
Not Found: /martcrm/assets/img/messages-2.jpg
Not Found: /martcrm/assets/img/messages-1.jpg
Not Found: /martcrm/assets/img/messages-3.jpg
Not Found: /martcrm/assets/img/profile-img.jpg
Email obj ====== EmailMaster object (47)
mobile_obj ====== MobileMaster object (47)
user_obj ====== {'_state': <django.db.models.base.ModelState object at 0x7f6d29060e80>, 'userid': 47, 'username': 'shaileshgola', 'password': 'rahul123!@#', 'title': None, 'fname': 'Shailesh', 'mname': '', 'lname': 'KUMAR', 'desg': 'Software Developer', 'creation_date': None, 'creation_time': None, 'last_visit': None, 'activation_code': None, 'auto_registered': None, 'buy_inquiry': None, 'sell_inquiry': None, 'webmail_status': '', 'account_status': '', 'section_id': None, 'heard_from': None, 'sms_balance': None, 'last_visit_time': None, 'id_verified': None, 'unmoderated_inq': None, 'tradealert_del_pref': None, 'terms_accepted': None, 'inq_orig_pref': None, 'generated_e': None, 'roaming_access': None, 'last_password_change': None, 'buy_rfis_limit': None, 'pw_hash': '', 'password_uncr': None, 'rfis_rate': None, 'avg_rfis_resp_time': None, 'show_rfis_rate': None, 'buyer_feedback': None, 'show_buyer_feedback': None, 'hide_rfis_rate': None, 'hide_buyer_feedback': None, 'inq_to_all_users': None, 'mark_inquiry_cc': None, 'user_image': None, 'miss_call_alert': None, 'merchant_account_id': None, 'google_tnc_accepted': None, 'google_ads_account_id': None, 'is_gmc_link_with_ads': None, 'adhaar_no': None, 'username_hi': None, 'desg_hi': None}
Profile obj ==  ProfileMaster object (36)
email_key ==  47
mobile_key ==  47
user_user_id ==== 47
null value in column "ifdefault" violates not-null constraint
DETAIL:  Failing row contains (47, 47, null, 2).

There is some error in company registration null value in column "ifdefault" violates not-null constraint
DETAIL:  Failing row contains (47, 47, null, 2).

Email obj ====== EmailMaster object (48)
mobile_obj ====== MobileMaster object (48)
user_obj ====== {'_state': <django.db.models.base.ModelState object at 0x7f6d290434f0>, 'userid': 48, 'username': 'shaileshgola', 'password': 'rahul123!@#', 'title': None, 'fname': 'Shailesh', 'mname': '', 'lname': 'KUMAR', 'desg': 'Software Developer', 'creation_date': None, 'creation_time': None, 'last_visit': None, 'activation_code': None, 'auto_registered': None, 'buy_inquiry': None, 'sell_inquiry': None, 'webmail_status': '', 'account_status': '', 'section_id': None, 'heard_from': None, 'sms_balance': None, 'last_visit_time': None, 'id_verified': None, 'unmoderated_inq': None, 'tradealert_del_pref': None, 'terms_accepted': None, 'inq_orig_pref': None, 'generated_e': None, 'roaming_access': None, 'last_password_change': None, 'buy_rfis_limit': None, 'pw_hash': '', 'password_uncr': None, 'rfis_rate': None, 'avg_rfis_resp_time': None, 'show_rfis_rate': None, 'buyer_feedback': None, 'show_buyer_feedback': None, 'hide_rfis_rate': None, 'hide_buyer_feedback': None, 'inq_to_all_users': None, 'mark_inquiry_cc': None, 'user_image': None, 'miss_call_alert': None, 'merchant_account_id': None, 'google_tnc_accepted': None, 'google_ads_account_id': None, 'is_gmc_link_with_ads': None, 'adhaar_no': None, 'username_hi': None, 'desg_hi': None}
Profile obj ==  ProfileMaster object (37)
email_key ==  48
mobile_key ==  48
user_user_id ==== 48
null value in column "ifdefault" violates not-null constraint
DETAIL:  Failing row contains (48, 48, null, 3).

There is some error in company registration null value in column "ifdefault" violates not-null constraint
DETAIL:  Failing row contains (48, 48, null, 3).

Email obj ====== EmailMaster object (49)
mobile_obj ====== MobileMaster object (49)
user_obj ====== {'_state': <django.db.models.base.ModelState object at 0x7f6d28feff10>, 'userid': 49, 'username': 'shaileshgola', 'password': 'rahul123!@#', 'title': None, 'fname': 'Shailesh', 'mname': '', 'lname': 'KUMAR', 'desg': 'Software Developer', 'creation_date': None, 'creation_time': None, 'last_visit': None, 'activation_code': None, 'auto_registered': None, 'buy_inquiry': None, 'sell_inquiry': None, 'webmail_status': '', 'account_status': '', 'section_id': None, 'heard_from': None, 'sms_balance': None, 'last_visit_time': None, 'id_verified': None, 'unmoderated_inq': None, 'tradealert_del_pref': None, 'terms_accepted': None, 'inq_orig_pref': None, 'generated_e': None, 'roaming_access': None, 'last_password_change': None, 'buy_rfis_limit': None, 'pw_hash': '', 'password_uncr': None, 'rfis_rate': None, 'avg_rfis_resp_time': None, 'show_rfis_rate': None, 'buyer_feedback': None, 'show_buyer_feedback': None, 'hide_rfis_rate': None, 'hide_buyer_feedback': None, 'inq_to_all_users': None, 'mark_inquiry_cc': None, 'user_image': None, 'miss_call_alert': None, 'merchant_account_id': None, 'google_tnc_accepted': None, 'google_ads_account_id': None, 'is_gmc_link_with_ads': None, 'adhaar_no': None, 'username_hi': None, 'desg_hi': None}
Profile obj ==  ProfileMaster object (38)
email_key ==  49
mobile_key ==  49
user_user_id ==== 49
null value in column "ifdefault" violates not-null constraint
DETAIL:  Failing row contains (49, 49, null, 4).

There is some error in company registration null value in column "ifdefault" violates not-null constraint
DETAIL:  Failing row contains (49, 49, null, 4).

Email obj ====== EmailMaster object (50)
mobile_obj ====== MobileMaster object (50)
user_obj ====== {'_state': <django.db.models.base.ModelState object at 0x7f6d28fb38b0>, 'userid': 50, 'username': 'shaileshgola', 'password': 'rahul123!@#', 'title': None, 'fname': 'Shailesh', 'mname': '', 'lname': 'KUMAR', 'desg': 'Software Developer', 'creation_date': None, 'creation_time': None, 'last_visit': None, 'activation_code': None, 'auto_registered': None, 'buy_inquiry': None, 'sell_inquiry': None, 'webmail_status': '', 'account_status': '', 'section_id': None, 'heard_from': None, 'sms_balance': None, 'last_visit_time': None, 'id_verified': None, 'unmoderated_inq': None, 'tradealert_del_pref': None, 'terms_accepted': None, 'inq_orig_pref': None, 'generated_e': None, 'roaming_access': None, 'last_password_change': None, 'buy_rfis_limit': None, 'pw_hash': '', 'password_uncr': None, 'rfis_rate': None, 'avg_rfis_resp_time': None, 'show_rfis_rate': None, 'buyer_feedback': None, 'show_buyer_feedback': None, 'hide_rfis_rate': None, 'hide_buyer_feedback': None, 'inq_to_all_users': None, 'mark_inquiry_cc': None, 'user_image': None, 'miss_call_alert': None, 'merchant_account_id': None, 'google_tnc_accepted': None, 'google_ads_account_id': None, 'is_gmc_link_with_ads': None, 'adhaar_no': None, 'username_hi': None, 'desg_hi': None}
Profile obj ==  ProfileMaster object (39)
email_key ==  50
mobile_key ==  50
user_user_id ==== 50
Profile====Obj == 39
Not Found: /martcrm/assets/img/logo.png
Not Found: /martcrm/assets/img/messages-1.jpg
Not Found: /martcrm/assets/img/messages-3.jpg
Not Found: /martcrm/assets/img/messages-2.jpg
Not Found: /martcrm/assets/img/profile-img.jpg
Not Found: /martcrm/assets/img/logo.png
Not Found: /martcrm/assets/img/messages-1.jpg
Not Found: /martcrm/assets/img/messages-3.jpg
Not Found: /martcrm/assets/img/messages-2.jpg
Not Found: /martcrm/assets/img/profile-img.jpg
Not Found: /martcrm/assets/img/logo.png
Not Found: /martcrm/assets/img/messages-1.jpg
Not Found: /martcrm/assets/img/messages-2.jpg
Not Found: /martcrm/assets/img/messages-3.jpg
Not Found: /martcrm/assets/img/profile-img.jpg
Not Found: /martcrm/assets/img/favicon.png
Not Found: /martcrm/assets/img/messages-1.jpg
Not Found: /martcrm/assets/img/logo.png
Not Found: /martcrm/assets/img/messages-2.jpg
Not Found: /martcrm/assets/img/messages-3.jpg
Not Found: /martcrm/assets/img/profile-img.jpg
Not Found: /martcrm/assets/img/favicon.png
Not Found: /
Not Found: /favicon.ico
Not Found: /martcrm/assets/img/logo.png
Not Found: /martcrm/assets/img/apple-touch-icon.png
Not Found: /martcrm/assets/img/favicon.png
Not Found: /martcrm/assets/img/logo.png
Not Found: /martcrm/assets/img/logo.png
Not Found: /martcrm/assets/img/logo.png
Not Found: /martcrm/assets/img/product-2.jpg
Not Found: /martcrm/assets/img/product-3.jpg
Not Found: /martcrm/assets/img/product-4.jpg
Not Found: /martcrm/assets/img/product-5.jpg
Not Found: /martcrm/assets/img/messages-3.jpg
Not Found: /martcrm/assets/img/news-1.jpg
Not Found: /martcrm/assets/img/news-2.jpg
Not Found: /martcrm/assets/img/product-1.jpg
Not Found: /martcrm/assets/img/messages-1.jpg
Not Found: /martcrm/assets/img/news-3.jpg
Not Found: /martcrm/assets/img/profile-img.jpg
Not Found: /martcrm/assets/img/news-4.jpg
Not Found: /martcrm/assets/img/news-5.jpg
Not Found: /martcrm/assets/img/messages-2.jpg
Not Found: /martcrm/assets/img/favicon.png
Not Found: /martcrm/assets/img/logo.png
Not Found: /martcrm/assets/img/messages-1.jpg
Not Found: /martcrm/assets/img/messages-2.jpg
Not Found: /martcrm/assets/img/messages-3.jpg
Not Found: /martcrm/assets/img/profile-img.jpg
Not Found: /martcrm/assets/img/messages-1.jpg
Not Found: /martcrm/assets/img/logo.png
Not Found: /martcrm/assets/img/messages-2.jpg
Not Found: /martcrm/assets/img/profile-img.jpg
Not Found: /martcrm/assets/img/messages-3.jpg
Not Found: /martcrm/assets/img/logo.png
Not Found: /martcrm/assets/img/messages-1.jpg
Not Found: /martcrm/assets/img/messages-3.jpg
Not Found: /martcrm/assets/img/messages-2.jpg
Not Found: /martcrm/assets/img/profile-img.jpg
Session None
Session None
Session 1
Session None
Not Found: /martcrm/assets/img/logo.png
Not Found: /martcrm/assets/img/favicon.png
Not Found: /martcrm/assets/img/messages-1.jpg
Not Found: /martcrm/assets/img/logo.png
Not Found: /martcrm/assets/img/messages-2.jpg
Not Found: /martcrm/assets/img/product-4.jpg
Not Found: /martcrm/assets/img/messages-3.jpg
Not Found: /martcrm/assets/img/product-5.jpg
Not Found: /martcrm/assets/img/profile-img.jpg
Not Found: /martcrm/assets/img/news-1.jpg
Not Found: /martcrm/assets/img/news-2.jpg
Not Found: /martcrm/assets/img/product-2.jpg
Not Found: /martcrm/assets/img/product-1.jpg
Not Found: /martcrm/assets/img/product-3.jpg
Not Found: /martcrm/assets/img/news-3.jpg
Not Found: /martcrm/assets/img/news-5.jpg
Not Found: /martcrm/assets/img/news-4.jpg
Session 2
Session None
Not Found: /martcrm/assets/img/logo.png
Not Found: /martcrm/assets/img/messages-1.jpg
Not Found: /martcrm/assets/img/messages-2.jpg
Not Found: /martcrm/assets/img/messages-3.jpg
Not Found: /martcrm/assets/img/profile-img.jpg
Not Found: /martcrm/assets/img/logo.png
Not Found: /martcrm/assets/img/messages-1.jpg
Not Found: /martcrm/assets/img/messages-3.jpg
Not Found: /martcrm/assets/img/messages-2.jpg
Not Found: /martcrm/assets/img/profile-img.jpg
Not Found: /martcrm/assets/img/logo.png
Not Found: /martcrm/assets/img/messages-1.jpg
Not Found: /martcrm/assets/img/messages-2.jpg
Not Found: /martcrm/assets/img/profile-img.jpg
Not Found: /martcrm/assets/img/messages-3.jpg
Not Found: /martcrm/assets/img/logo.png
Not Found: /martcrm/assets/img/messages-1.jpg
Not Found: /martcrm/assets/img/messages-3.jpg
Not Found: /martcrm/assets/img/messages-2.jpg
Not Found: /martcrm/assets/img/profile-img.jpg
Not Found: /martcrm/assets/img/logo.png
Not Found: /martcrm/assets/img/messages-1.jpg
Not Found: /martcrm/assets/img/messages-3.jpg
Not Found: /martcrm/assets/img/messages-2.jpg
Not Found: /martcrm/assets/img/profile-img.jpg
Not Found: /martcrm/assets/img/logo.png
Not Found: /martcrm/assets/img/messages-1.jpg
Not Found: /martcrm/assets/img/messages-2.jpg
Not Found: /martcrm/assets/img/profile-img.jpg
Not Found: /martcrm/assets/img/messages-3.jpg
Not Found: /martcrm/index.html
Not Found: /favicon.ico
Not Found: /index.php
Not Found: /index.php
Not Found: /index.php
Not Found: /index.php
Not Found: /index.php
Not Found: /index.php
Not Found: /martcrm/assets/img/logo.png
Not Found: /martcrm/assets/img/messages-3.jpg
Not Found: /martcrm/assets/img/messages-1.jpg
Not Found: /martcrm/assets/img/messages-2.jpg
Not Found: /martcrm/assets/img/profile-img.jpg
Not Found: /martcrm/assets/img/logo.png
Not Found: /martcrm/assets/img/messages-1.jpg
Not Found: /martcrm/assets/img/profile-img.jpg
Not Found: /martcrm/assets/img/messages-3.jpg
Not Found: /martcrm/assets/img/messages-2.jpg
Not Found: /martcrm/assets/img/logo.png
Not Found: /martcrm/assets/img/messages-2.jpg
Not Found: /martcrm/assets/img/messages-1.jpg
Not Found: /martcrm/assets/img/messages-3.jpg
Not Found: /martcrm/assets/img/profile-img.jpg
Not Found: /martcrm/assets/img/logo.png
Not Found: /martcrm/assets/img/messages-1.jpg
Not Found: /martcrm/assets/img/messages-3.jpg
Not Found: /martcrm/assets/img/messages-2.jpg
Not Found: /martcrm/assets/img/profile-img.jpg
Not Found: /martcrm/assets/img/logo.png
Not Found: /martcrm/assets/img/messages-1.jpg
Not Found: /martcrm/assets/img/messages-2.jpg
Not Found: /martcrm/assets/img/profile-img.jpg
Not Found: /martcrm/assets/img/messages-3.jpg
